2024-06-09 03:50:36 django.template  /home/jn/.local/lib/python3.10/site-packages/django/template/base.py:869 base:_resolve_lookup DEBUG- Exception while resolving variable 'page_title' in template 'voting/voter/result.html'.
Traceback (most recent call last):
  File "/home/jn/.local/lib/python3.10/site-packages/django/template/base.py", line 829, in _resolve_lookup
    current = current[bit]
  File "/home/jn/.local/lib/python3.10/site-packages/django/template/context.py", line 83, in __getitem__
    raise KeyError(key)
KeyError: 'page_title'

During handling of the above exception, another exception occurred:

Traceback (most recent call last):
  File "/home/jn/.local/lib/python3.10/site-packages/django/template/base.py", line 835, in _resolve_lookup
    if isinstance(current, BaseContext) and getattr(type(current), bit):
AttributeError: type object 'RequestContext' has no attribute 'page_title'

During handling of the above exception, another exception occurred:

Traceback (most recent call last):
  File "/home/jn/.local/lib/python3.10/site-packages/django/template/base.py", line 843, in _resolve_lookup
    current = current[int(bit)]
ValueError: invalid literal for int() with base 10: 'page_title'

During handling of the above exception, another exception occurred:

Traceback (most recent call last):
  File "/home/jn/.local/lib/python3.10/site-packages/django/template/base.py", line 848, in _resolve_lookup
    raise VariableDoesNotExist("Failed lookup for key "
django.template.base.VariableDoesNotExist: Failed lookup for key [page_title] in [{'True': True, 'False': False, 'None': None}, {'csrf_token': <SimpleLazyObject: 'hL247UXah0vYFJr3BBxNkCkETJq3wQIIgx0slQvNgNgvAxoNYcl6xXzG4dY6oSPa'>, 'request': <WSGIRequest: GET '/voting/dashboard/'>, 'user': <SimpleLazyObject: <CustomUser: 橙 子>>, 'perms': <django.contrib.auth.context_processors.PermWrapper object at 0x7f11d40132e0>, 'messages': <django.contrib.messages.storage.fallback.FallbackStorage object at 0x7f11d41c3670>, 'DEFAULT_MESSAGE_LEVELS': {'DEBUG': 10, 'INFO': 20, 'SUCCESS': 25, 'WARNING': 30, 'ERROR': 40}, 'TITLE': '班级选举'}, {}, {'my_votes': <QuerySet [<Votes: Votes object (3)>]>}]
2024-06-09 03:50:36 django.template  /home/jn/.local/lib/python3.10/site-packages/django/template/base.py:869 base:_resolve_lookup DEBUG- Exception while resolving variable 'page_title' in template 'voting/voter/result.html'.
Traceback (most recent call last):
  File "/home/jn/.local/lib/python3.10/site-packages/django/template/base.py", line 829, in _resolve_lookup
    current = current[bit]
  File "/home/jn/.local/lib/python3.10/site-packages/django/template/context.py", line 83, in __getitem__
    raise KeyError(key)
KeyError: 'page_title'

During handling of the above exception, another exception occurred:

Traceback (most recent call last):
  File "/home/jn/.local/lib/python3.10/site-packages/django/template/base.py", line 835, in _resolve_lookup
    if isinstance(current, BaseContext) and getattr(type(current), bit):
AttributeError: type object 'RequestContext' has no attribute 'page_title'

During handling of the above exception, another exception occurred:

Traceback (most recent call last):
  File "/home/jn/.local/lib/python3.10/site-packages/django/template/base.py", line 843, in _resolve_lookup
    current = current[int(bit)]
ValueError: invalid literal for int() with base 10: 'page_title'

During handling of the above exception, another exception occurred:

Traceback (most recent call last):
  File "/home/jn/.local/lib/python3.10/site-packages/django/template/base.py", line 848, in _resolve_lookup
    raise VariableDoesNotExist("Failed lookup for key "
django.template.base.VariableDoesNotExist: Failed lookup for key [page_title] in [{'True': True, 'False': False, 'None': None}, {'csrf_token': <SimpleLazyObject: 'hL247UXah0vYFJr3BBxNkCkETJq3wQIIgx0slQvNgNgvAxoNYcl6xXzG4dY6oSPa'>, 'request': <WSGIRequest: GET '/voting/dashboard/'>, 'user': <SimpleLazyObject: <CustomUser: 橙 子>>, 'perms': <django.contrib.auth.context_processors.PermWrapper object at 0x7f11d40132e0>, 'messages': <django.contrib.messages.storage.fallback.FallbackStorage object at 0x7f11d41c3670>, 'DEFAULT_MESSAGE_LEVELS': {'DEBUG': 10, 'INFO': 20, 'SUCCESS': 25, 'WARNING': 30, 'ERROR': 40}, 'TITLE': '班级选举'}, {}, {'my_votes': <QuerySet [<Votes: Votes object (3)>]>}]
2024-06-09 03:50:39 django.template  /home/jn/.local/lib/python3.10/site-packages/django/template/base.py:869 base:_resolve_lookup DEBUG- Exception while resolving variable 'name' in template 'unknown'.
Traceback (most recent call last):
  File "/home/jn/.local/lib/python3.10/site-packages/django/core/handlers/exception.py", line 47, in inner
    response = get_response(request)
  File "/home/jn/.local/lib/python3.10/site-packages/django/core/handlers/base.py", line 165, in _get_response
    callback, callback_args, callback_kwargs = self.resolve_request(request)
  File "/home/jn/.local/lib/python3.10/site-packages/django/core/handlers/base.py", line 288, in resolve_request
    resolver_match = resolver.resolve(request.path_info)
  File "/home/jn/.local/lib/python3.10/site-packages/django/urls/resolvers.py", line 576, in resolve
    raise Resolver404({'tried': tried, 'path': new_path})
django.urls.exceptions.Resolver404: {'tried': [[<URLResolver <module 'account.urls' from '/mnt/c/Users/JackieNan/Projects/votingsystem/account/urls.py'> (None:None) ''>, <URLPattern '' [name='account_login']>], [<URLResolver <module 'account.urls' from '/mnt/c/Users/JackieNan/Projects/votingsystem/account/urls.py'> (None:None) ''>, <URLPattern 'register/' [name='account_register']>], [<URLResolver <module 'account.urls' from '/mnt/c/Users/JackieNan/Projects/votingsystem/account/urls.py'> (None:None) ''>, <URLPattern 'logout/' [name='account_logout']>], [<URLResolver <module 'account.urls' from '/mnt/c/Users/JackieNan/Projects/votingsystem/account/urls.py'> (None:None) 'account/'>], [<URLResolver <URLPattern list> (admin:admin) 'admin/'>], [<URLResolver <module 'administrator.urls' from '/mnt/c/Users/JackieNan/Projects/votingsystem/administrator/urls.py'> (None:None) 'administrator/'>], [<URLResolver <module 'voting.urls' from '/mnt/c/Users/JackieNan/Projects/votingsystem/voting/urls.py'> (None:None) 'voting/'>], [<URLPattern '^media/(?P<path>.*)$'>]], 'path': 'favicon.ico'}

During handling of the above exception, another exception occurred:

Traceback (most recent call last):
  File "/home/jn/.local/lib/python3.10/site-packages/django/template/base.py", line 829, in _resolve_lookup
    current = current[bit]
TypeError: 'URLResolver' object is not subscriptable

During handling of the above exception, another exception occurred:

Traceback (most recent call last):
  File "/home/jn/.local/lib/python3.10/site-packages/django/template/base.py", line 837, in _resolve_lookup
    current = getattr(current, bit)
AttributeError: 'URLResolver' object has no attribute 'name'

During handling of the above exception, another exception occurred:

Traceback (most recent call last):
  File "/home/jn/.local/lib/python3.10/site-packages/django/template/base.py", line 843, in _resolve_lookup
    current = current[int(bit)]
ValueError: invalid literal for int() with base 10: 'name'

During handling of the above exception, another exception occurred:

Traceback (most recent call last):
  File "/home/jn/.local/lib/python3.10/site-packages/django/template/base.py", line 848, in _resolve_lookup
    raise VariableDoesNotExist("Failed lookup for key "
django.template.base.VariableDoesNotExist: Failed lookup for key [name] in <URLResolver <module 'account.urls' from '/mnt/c/Users/JackieNan/Projects/votingsystem/account/urls.py'> (None:None) 'account/'>
2024-06-09 03:50:39 django.template  /home/jn/.local/lib/python3.10/site-packages/django/template/base.py:869 base:_resolve_lookup DEBUG- Exception while resolving variable 'name' in template 'unknown'.
Traceback (most recent call last):
  File "/home/jn/.local/lib/python3.10/site-packages/django/core/handlers/exception.py", line 47, in inner
    response = get_response(request)
  File "/home/jn/.local/lib/python3.10/site-packages/django/core/handlers/base.py", line 165, in _get_response
    callback, callback_args, callback_kwargs = self.resolve_request(request)
  File "/home/jn/.local/lib/python3.10/site-packages/django/core/handlers/base.py", line 288, in resolve_request
    resolver_match = resolver.resolve(request.path_info)
  File "/home/jn/.local/lib/python3.10/site-packages/django/urls/resolvers.py", line 576, in resolve
    raise Resolver404({'tried': tried, 'path': new_path})
django.urls.exceptions.Resolver404: {'tried': [[<URLResolver <module 'account.urls' from '/mnt/c/Users/JackieNan/Projects/votingsystem/account/urls.py'> (None:None) ''>, <URLPattern '' [name='account_login']>], [<URLResolver <module 'account.urls' from '/mnt/c/Users/JackieNan/Projects/votingsystem/account/urls.py'> (None:None) ''>, <URLPattern 'register/' [name='account_register']>], [<URLResolver <module 'account.urls' from '/mnt/c/Users/JackieNan/Projects/votingsystem/account/urls.py'> (None:None) ''>, <URLPattern 'logout/' [name='account_logout']>], [<URLResolver <module 'account.urls' from '/mnt/c/Users/JackieNan/Projects/votingsystem/account/urls.py'> (None:None) 'account/'>], [<URLResolver <URLPattern list> (admin:admin) 'admin/'>], [<URLResolver <module 'administrator.urls' from '/mnt/c/Users/JackieNan/Projects/votingsystem/administrator/urls.py'> (None:None) 'administrator/'>], [<URLResolver <module 'voting.urls' from '/mnt/c/Users/JackieNan/Projects/votingsystem/voting/urls.py'> (None:None) 'voting/'>], [<URLPattern '^media/(?P<path>.*)$'>]], 'path': 'favicon.ico'}

During handling of the above exception, another exception occurred:

Traceback (most recent call last):
  File "/home/jn/.local/lib/python3.10/site-packages/django/template/base.py", line 829, in _resolve_lookup
    current = current[bit]
TypeError: 'URLResolver' object is not subscriptable

During handling of the above exception, another exception occurred:

Traceback (most recent call last):
  File "/home/jn/.local/lib/python3.10/site-packages/django/template/base.py", line 837, in _resolve_lookup
    current = getattr(current, bit)
AttributeError: 'URLResolver' object has no attribute 'name'

During handling of the above exception, another exception occurred:

Traceback (most recent call last):
  File "/home/jn/.local/lib/python3.10/site-packages/django/template/base.py", line 843, in _resolve_lookup
    current = current[int(bit)]
ValueError: invalid literal for int() with base 10: 'name'

During handling of the above exception, another exception occurred:

Traceback (most recent call last):
  File "/home/jn/.local/lib/python3.10/site-packages/django/template/base.py", line 848, in _resolve_lookup
    raise VariableDoesNotExist("Failed lookup for key "
django.template.base.VariableDoesNotExist: Failed lookup for key [name] in <URLResolver <URLPattern list> (admin:admin) 'admin/'>
2024-06-09 03:50:39 django.template  /home/jn/.local/lib/python3.10/site-packages/django/template/base.py:869 base:_resolve_lookup DEBUG- Exception while resolving variable 'name' in template 'unknown'.
Traceback (most recent call last):
  File "/home/jn/.local/lib/python3.10/site-packages/django/core/handlers/exception.py", line 47, in inner
    response = get_response(request)
  File "/home/jn/.local/lib/python3.10/site-packages/django/core/handlers/base.py", line 165, in _get_response
    callback, callback_args, callback_kwargs = self.resolve_request(request)
  File "/home/jn/.local/lib/python3.10/site-packages/django/core/handlers/base.py", line 288, in resolve_request
    resolver_match = resolver.resolve(request.path_info)
  File "/home/jn/.local/lib/python3.10/site-packages/django/urls/resolvers.py", line 576, in resolve
    raise Resolver404({'tried': tried, 'path': new_path})
django.urls.exceptions.Resolver404: {'tried': [[<URLResolver <module 'account.urls' from '/mnt/c/Users/JackieNan/Projects/votingsystem/account/urls.py'> (None:None) ''>, <URLPattern '' [name='account_login']>], [<URLResolver <module 'account.urls' from '/mnt/c/Users/JackieNan/Projects/votingsystem/account/urls.py'> (None:None) ''>, <URLPattern 'register/' [name='account_register']>], [<URLResolver <module 'account.urls' from '/mnt/c/Users/JackieNan/Projects/votingsystem/account/urls.py'> (None:None) ''>, <URLPattern 'logout/' [name='account_logout']>], [<URLResolver <module 'account.urls' from '/mnt/c/Users/JackieNan/Projects/votingsystem/account/urls.py'> (None:None) 'account/'>], [<URLResolver <URLPattern list> (admin:admin) 'admin/'>], [<URLResolver <module 'administrator.urls' from '/mnt/c/Users/JackieNan/Projects/votingsystem/administrator/urls.py'> (None:None) 'administrator/'>], [<URLResolver <module 'voting.urls' from '/mnt/c/Users/JackieNan/Projects/votingsystem/voting/urls.py'> (None:None) 'voting/'>], [<URLPattern '^media/(?P<path>.*)$'>]], 'path': 'favicon.ico'}

During handling of the above exception, another exception occurred:

Traceback (most recent call last):
  File "/home/jn/.local/lib/python3.10/site-packages/django/template/base.py", line 829, in _resolve_lookup
    current = current[bit]
TypeError: 'URLResolver' object is not subscriptable

During handling of the above exception, another exception occurred:

Traceback (most recent call last):
  File "/home/jn/.local/lib/python3.10/site-packages/django/template/base.py", line 837, in _resolve_lookup
    current = getattr(current, bit)
AttributeError: 'URLResolver' object has no attribute 'name'

During handling of the above exception, another exception occurred:

Traceback (most recent call last):
  File "/home/jn/.local/lib/python3.10/site-packages/django/template/base.py", line 843, in _resolve_lookup
    current = current[int(bit)]
ValueError: invalid literal for int() with base 10: 'name'

During handling of the above exception, another exception occurred:

Traceback (most recent call last):
  File "/home/jn/.local/lib/python3.10/site-packages/django/template/base.py", line 848, in _resolve_lookup
    raise VariableDoesNotExist("Failed lookup for key "
django.template.base.VariableDoesNotExist: Failed lookup for key [name] in <URLResolver <module 'administrator.urls' from '/mnt/c/Users/JackieNan/Projects/votingsystem/administrator/urls.py'> (None:None) 'administrator/'>
2024-06-09 03:50:39 django.template  /home/jn/.local/lib/python3.10/site-packages/django/template/base.py:869 base:_resolve_lookup DEBUG- Exception while resolving variable 'name' in template 'unknown'.
Traceback (most recent call last):
  File "/home/jn/.local/lib/python3.10/site-packages/django/core/handlers/exception.py", line 47, in inner
    response = get_response(request)
  File "/home/jn/.local/lib/python3.10/site-packages/django/core/handlers/base.py", line 165, in _get_response
    callback, callback_args, callback_kwargs = self.resolve_request(request)
  File "/home/jn/.local/lib/python3.10/site-packages/django/core/handlers/base.py", line 288, in resolve_request
    resolver_match = resolver.resolve(request.path_info)
  File "/home/jn/.local/lib/python3.10/site-packages/django/urls/resolvers.py", line 576, in resolve
    raise Resolver404({'tried': tried, 'path': new_path})
django.urls.exceptions.Resolver404: {'tried': [[<URLResolver <module 'account.urls' from '/mnt/c/Users/JackieNan/Projects/votingsystem/account/urls.py'> (None:None) ''>, <URLPattern '' [name='account_login']>], [<URLResolver <module 'account.urls' from '/mnt/c/Users/JackieNan/Projects/votingsystem/account/urls.py'> (None:None) ''>, <URLPattern 'register/' [name='account_register']>], [<URLResolver <module 'account.urls' from '/mnt/c/Users/JackieNan/Projects/votingsystem/account/urls.py'> (None:None) ''>, <URLPattern 'logout/' [name='account_logout']>], [<URLResolver <module 'account.urls' from '/mnt/c/Users/JackieNan/Projects/votingsystem/account/urls.py'> (None:None) 'account/'>], [<URLResolver <URLPattern list> (admin:admin) 'admin/'>], [<URLResolver <module 'administrator.urls' from '/mnt/c/Users/JackieNan/Projects/votingsystem/administrator/urls.py'> (None:None) 'administrator/'>], [<URLResolver <module 'voting.urls' from '/mnt/c/Users/JackieNan/Projects/votingsystem/voting/urls.py'> (None:None) 'voting/'>], [<URLPattern '^media/(?P<path>.*)$'>]], 'path': 'favicon.ico'}

During handling of the above exception, another exception occurred:

Traceback (most recent call last):
  File "/home/jn/.local/lib/python3.10/site-packages/django/template/base.py", line 829, in _resolve_lookup
    current = current[bit]
TypeError: 'URLResolver' object is not subscriptable

During handling of the above exception, another exception occurred:

Traceback (most recent call last):
  File "/home/jn/.local/lib/python3.10/site-packages/django/template/base.py", line 837, in _resolve_lookup
    current = getattr(current, bit)
AttributeError: 'URLResolver' object has no attribute 'name'

During handling of the above exception, another exception occurred:

Traceback (most recent call last):
  File "/home/jn/.local/lib/python3.10/site-packages/django/template/base.py", line 843, in _resolve_lookup
    current = current[int(bit)]
ValueError: invalid literal for int() with base 10: 'name'

During handling of the above exception, another exception occurred:

Traceback (most recent call last):
  File "/home/jn/.local/lib/python3.10/site-packages/django/template/base.py", line 848, in _resolve_lookup
    raise VariableDoesNotExist("Failed lookup for key "
django.template.base.VariableDoesNotExist: Failed lookup for key [name] in <URLResolver <module 'voting.urls' from '/mnt/c/Users/JackieNan/Projects/votingsystem/voting/urls.py'> (None:None) 'voting/'>
2024-06-09 03:51:23 django.template  /home/jn/.local/lib/python3.10/site-packages/django/template/base.py:869 base:_resolve_lookup DEBUG- Exception while resolving variable '职位计数' in template 'admin/home.html'.
Traceback (most recent call last):
  File "/home/jn/.local/lib/python3.10/site-packages/django/template/base.py", line 829, in _resolve_lookup
    current = current[bit]
  File "/home/jn/.local/lib/python3.10/site-packages/django/template/context.py", line 83, in __getitem__
    raise KeyError(key)
KeyError: '职位计数'

During handling of the above exception, another exception occurred:

Traceback (most recent call last):
  File "/home/jn/.local/lib/python3.10/site-packages/django/template/base.py", line 835, in _resolve_lookup
    if isinstance(current, BaseContext) and getattr(type(current), bit):
AttributeError: type object 'RequestContext' has no attribute '职位计数'

During handling of the above exception, another exception occurred:

Traceback (most recent call last):
  File "/home/jn/.local/lib/python3.10/site-packages/django/template/base.py", line 843, in _resolve_lookup
    current = current[int(bit)]
ValueError: invalid literal for int() with base 10: '职位计数'

During handling of the above exception, another exception occurred:

Traceback (most recent call last):
  File "/home/jn/.local/lib/python3.10/site-packages/django/template/base.py", line 848, in _resolve_lookup
    raise VariableDoesNotExist("Failed lookup for key "
django.template.base.VariableDoesNotExist: Failed lookup for key [职位计数] in [{'True': True, 'False': False, 'None': None}, {'csrf_token': <SimpleLazyObject: 'BUB4CtbTTs9d3OJFMXZIoVppXmb0PugITrnqENoNGtLqUS04SYyqUd2xD53YdjbF'>, 'request': <WSGIRequest: GET '/administrator/'>, 'user': <SimpleLazyObject: <CustomUser: System Administrator>>, 'perms': <django.contrib.auth.context_processors.PermWrapper object at 0x7f11d40b66b0>, 'messages': <django.contrib.messages.storage.fallback.FallbackStorage object at 0x7f11d4184d60>, 'DEFAULT_MESSAGE_LEVELS': {'DEBUG': 10, 'INFO': 20, 'SUCCESS': 25, 'WARNING': 30, 'ERROR': 40}, 'TITLE': '班级选举'}, {}, {'position_count': 1, 'candidate_count': 2, 'voters_count': 3, 'voted_voters_count': 3, 'positions': <QuerySet [<Position: q>]>, 'chart_data': {<Position: q>: {'candidates': ['a', 'b'], 'votes': [3, 0], 'pos_id': 1}}, 'page_title': '主页'}, {'block': <Block Node: content. Contents: [<TextNode: '\n<!-- Main content -->\n  '>, <Variable Node: 职位计数>, <TextNode: '</h3>\n              <p>职位'>, <django.template.defaulttags.URLNode object at 0x7f11ccec41c0>, <TextNode: '" class="small-box-footer'>, <Variable Node: 候选人计数>, <TextNode: '</h3>          \n         '>, <django.template.defaulttags.URLNode object at 0x7f11ccec4430>, <TextNode: '" class="small-box-footer'>, <Variable Node: 投票计数>, <TextNode: '</h3>             \n      '>, <django.template.defaulttags.URLNode object at 0x7f11ccec46a0>, <TextNode: '" class="small-box-footer'>, <Variable Node: 已投票选民计数>, <TextNode: '</h3>\n              <p>已投'>, <django.template.defaulttags.URLNode object at 0x7f11ccec4910>, <TextNode: '" class="small-box-footer'>, <django.template.defaulttags.URLNode object at 0x7f11ccec49a0>, <TextNode: '" class="btn btn-success '>, <ForNode: for position in positions, tail_len: 9>, <TextNode: '\n     '>, <IfNode>, <TextNode: '\n      </section>\n      \n'>]>}]
2024-06-09 03:51:23 django.template  /home/jn/.local/lib/python3.10/site-packages/django/template/base.py:869 base:_resolve_lookup DEBUG- Exception while resolving variable '候选人计数' in template 'admin/home.html'.
Traceback (most recent call last):
  File "/home/jn/.local/lib/python3.10/site-packages/django/template/base.py", line 829, in _resolve_lookup
    current = current[bit]
  File "/home/jn/.local/lib/python3.10/site-packages/django/template/context.py", line 83, in __getitem__
    raise KeyError(key)
KeyError: '候选人计数'

During handling of the above exception, another exception occurred:

Traceback (most recent call last):
  File "/home/jn/.local/lib/python3.10/site-packages/django/template/base.py", line 835, in _resolve_lookup
    if isinstance(current, BaseContext) and getattr(type(current), bit):
AttributeError: type object 'RequestContext' has no attribute '候选人计数'

During handling of the above exception, another exception occurred:

Traceback (most recent call last):
  File "/home/jn/.local/lib/python3.10/site-packages/django/template/base.py", line 843, in _resolve_lookup
    current = current[int(bit)]
ValueError: invalid literal for int() with base 10: '候选人计数'

During handling of the above exception, another exception occurred:

Traceback (most recent call last):
  File "/home/jn/.local/lib/python3.10/site-packages/django/template/base.py", line 848, in _resolve_lookup
    raise VariableDoesNotExist("Failed lookup for key "
django.template.base.VariableDoesNotExist: Failed lookup for key [候选人计数] in [{'True': True, 'False': False, 'None': None}, {'csrf_token': <SimpleLazyObject: 'BUB4CtbTTs9d3OJFMXZIoVppXmb0PugITrnqENoNGtLqUS04SYyqUd2xD53YdjbF'>, 'request': <WSGIRequest: GET '/administrator/'>, 'user': <SimpleLazyObject: <CustomUser: System Administrator>>, 'perms': <django.contrib.auth.context_processors.PermWrapper object at 0x7f11d40b66b0>, 'messages': <django.contrib.messages.storage.fallback.FallbackStorage object at 0x7f11d4184d60>, 'DEFAULT_MESSAGE_LEVELS': {'DEBUG': 10, 'INFO': 20, 'SUCCESS': 25, 'WARNING': 30, 'ERROR': 40}, 'TITLE': '班级选举'}, {}, {'position_count': 1, 'candidate_count': 2, 'voters_count': 3, 'voted_voters_count': 3, 'positions': <QuerySet [<Position: q>]>, 'chart_data': {<Position: q>: {'candidates': ['a', 'b'], 'votes': [3, 0], 'pos_id': 1}}, 'page_title': '主页'}, {'block': <Block Node: content. Contents: [<TextNode: '\n<!-- Main content -->\n  '>, <Variable Node: 职位计数>, <TextNode: '</h3>\n              <p>职位'>, <django.template.defaulttags.URLNode object at 0x7f11ccec41c0>, <TextNode: '" class="small-box-footer'>, <Variable Node: 候选人计数>, <TextNode: '</h3>          \n         '>, <django.template.defaulttags.URLNode object at 0x7f11ccec4430>, <TextNode: '" class="small-box-footer'>, <Variable Node: 投票计数>, <TextNode: '</h3>             \n      '>, <django.template.defaulttags.URLNode object at 0x7f11ccec46a0>, <TextNode: '" class="small-box-footer'>, <Variable Node: 已投票选民计数>, <TextNode: '</h3>\n              <p>已投'>, <django.template.defaulttags.URLNode object at 0x7f11ccec4910>, <TextNode: '" class="small-box-footer'>, <django.template.defaulttags.URLNode object at 0x7f11ccec49a0>, <TextNode: '" class="btn btn-success '>, <ForNode: for position in positions, tail_len: 9>, <TextNode: '\n     '>, <IfNode>, <TextNode: '\n      </section>\n      \n'>]>}]
2024-06-09 03:51:23 django.template  /home/jn/.local/lib/python3.10/site-packages/django/template/base.py:869 base:_resolve_lookup DEBUG- Exception while resolving variable '投票计数' in template 'admin/home.html'.
Traceback (most recent call last):
  File "/home/jn/.local/lib/python3.10/site-packages/django/template/base.py", line 829, in _resolve_lookup
    current = current[bit]
  File "/home/jn/.local/lib/python3.10/site-packages/django/template/context.py", line 83, in __getitem__
    raise KeyError(key)
KeyError: '投票计数'

During handling of the above exception, another exception occurred:

Traceback (most recent call last):
  File "/home/jn/.local/lib/python3.10/site-packages/django/template/base.py", line 835, in _resolve_lookup
    if isinstance(current, BaseContext) and getattr(type(current), bit):
AttributeError: type object 'RequestContext' has no attribute '投票计数'

During handling of the above exception, another exception occurred:

Traceback (most recent call last):
  File "/home/jn/.local/lib/python3.10/site-packages/django/template/base.py", line 843, in _resolve_lookup
    current = current[int(bit)]
ValueError: invalid literal for int() with base 10: '投票计数'

During handling of the above exception, another exception occurred:

Traceback (most recent call last):
  File "/home/jn/.local/lib/python3.10/site-packages/django/template/base.py", line 848, in _resolve_lookup
    raise VariableDoesNotExist("Failed lookup for key "
django.template.base.VariableDoesNotExist: Failed lookup for key [投票计数] in [{'True': True, 'False': False, 'None': None}, {'csrf_token': <SimpleLazyObject: 'BUB4CtbTTs9d3OJFMXZIoVppXmb0PugITrnqENoNGtLqUS04SYyqUd2xD53YdjbF'>, 'request': <WSGIRequest: GET '/administrator/'>, 'user': <SimpleLazyObject: <CustomUser: System Administrator>>, 'perms': <django.contrib.auth.context_processors.PermWrapper object at 0x7f11d40b66b0>, 'messages': <django.contrib.messages.storage.fallback.FallbackStorage object at 0x7f11d4184d60>, 'DEFAULT_MESSAGE_LEVELS': {'DEBUG': 10, 'INFO': 20, 'SUCCESS': 25, 'WARNING': 30, 'ERROR': 40}, 'TITLE': '班级选举'}, {}, {'position_count': 1, 'candidate_count': 2, 'voters_count': 3, 'voted_voters_count': 3, 'positions': <QuerySet [<Position: q>]>, 'chart_data': {<Position: q>: {'candidates': ['a', 'b'], 'votes': [3, 0], 'pos_id': 1}}, 'page_title': '主页'}, {'block': <Block Node: content. Contents: [<TextNode: '\n<!-- Main content -->\n  '>, <Variable Node: 职位计数>, <TextNode: '</h3>\n              <p>职位'>, <django.template.defaulttags.URLNode object at 0x7f11ccec41c0>, <TextNode: '" class="small-box-footer'>, <Variable Node: 候选人计数>, <TextNode: '</h3>          \n         '>, <django.template.defaulttags.URLNode object at 0x7f11ccec4430>, <TextNode: '" class="small-box-footer'>, <Variable Node: 投票计数>, <TextNode: '</h3>             \n      '>, <django.template.defaulttags.URLNode object at 0x7f11ccec46a0>, <TextNode: '" class="small-box-footer'>, <Variable Node: 已投票选民计数>, <TextNode: '</h3>\n              <p>已投'>, <django.template.defaulttags.URLNode object at 0x7f11ccec4910>, <TextNode: '" class="small-box-footer'>, <django.template.defaulttags.URLNode object at 0x7f11ccec49a0>, <TextNode: '" class="btn btn-success '>, <ForNode: for position in positions, tail_len: 9>, <TextNode: '\n     '>, <IfNode>, <TextNode: '\n      </section>\n      \n'>]>}]
2024-06-09 03:51:23 django.template  /home/jn/.local/lib/python3.10/site-packages/django/template/base.py:869 base:_resolve_lookup DEBUG- Exception while resolving variable '已投票选民计数' in template 'admin/home.html'.
Traceback (most recent call last):
  File "/home/jn/.local/lib/python3.10/site-packages/django/template/base.py", line 829, in _resolve_lookup
    current = current[bit]
  File "/home/jn/.local/lib/python3.10/site-packages/django/template/context.py", line 83, in __getitem__
    raise KeyError(key)
KeyError: '已投票选民计数'

During handling of the above exception, another exception occurred:

Traceback (most recent call last):
  File "/home/jn/.local/lib/python3.10/site-packages/django/template/base.py", line 835, in _resolve_lookup
    if isinstance(current, BaseContext) and getattr(type(current), bit):
AttributeError: type object 'RequestContext' has no attribute '已投票选民计数'

During handling of the above exception, another exception occurred:

Traceback (most recent call last):
  File "/home/jn/.local/lib/python3.10/site-packages/django/template/base.py", line 843, in _resolve_lookup
    current = current[int(bit)]
ValueError: invalid literal for int() with base 10: '已投票选民计数'

During handling of the above exception, another exception occurred:

Traceback (most recent call last):
  File "/home/jn/.local/lib/python3.10/site-packages/django/template/base.py", line 848, in _resolve_lookup
    raise VariableDoesNotExist("Failed lookup for key "
django.template.base.VariableDoesNotExist: Failed lookup for key [已投票选民计数] in [{'True': True, 'False': False, 'None': None}, {'csrf_token': <SimpleLazyObject: 'BUB4CtbTTs9d3OJFMXZIoVppXmb0PugITrnqENoNGtLqUS04SYyqUd2xD53YdjbF'>, 'request': <WSGIRequest: GET '/administrator/'>, 'user': <SimpleLazyObject: <CustomUser: System Administrator>>, 'perms': <django.contrib.auth.context_processors.PermWrapper object at 0x7f11d40b66b0>, 'messages': <django.contrib.messages.storage.fallback.FallbackStorage object at 0x7f11d4184d60>, 'DEFAULT_MESSAGE_LEVELS': {'DEBUG': 10, 'INFO': 20, 'SUCCESS': 25, 'WARNING': 30, 'ERROR': 40}, 'TITLE': '班级选举'}, {}, {'position_count': 1, 'candidate_count': 2, 'voters_count': 3, 'voted_voters_count': 3, 'positions': <QuerySet [<Position: q>]>, 'chart_data': {<Position: q>: {'candidates': ['a', 'b'], 'votes': [3, 0], 'pos_id': 1}}, 'page_title': '主页'}, {'block': <Block Node: content. Contents: [<TextNode: '\n<!-- Main content -->\n  '>, <Variable Node: 职位计数>, <TextNode: '</h3>\n              <p>职位'>, <django.template.defaulttags.URLNode object at 0x7f11ccec41c0>, <TextNode: '" class="small-box-footer'>, <Variable Node: 候选人计数>, <TextNode: '</h3>          \n         '>, <django.template.defaulttags.URLNode object at 0x7f11ccec4430>, <TextNode: '" class="small-box-footer'>, <Variable Node: 投票计数>, <TextNode: '</h3>             \n      '>, <django.template.defaulttags.URLNode object at 0x7f11ccec46a0>, <TextNode: '" class="small-box-footer'>, <Variable Node: 已投票选民计数>, <TextNode: '</h3>\n              <p>已投'>, <django.template.defaulttags.URLNode object at 0x7f11ccec4910>, <TextNode: '" class="small-box-footer'>, <django.template.defaulttags.URLNode object at 0x7f11ccec49a0>, <TextNode: '" class="btn btn-success '>, <ForNode: for position in positions, tail_len: 9>, <TextNode: '\n     '>, <IfNode>, <TextNode: '\n      </section>\n      \n'>]>}]
2024-06-09 03:51:23 django.template  /home/jn/.local/lib/python3.10/site-packages/django/template/base.py:869 base:_resolve_lookup DEBUG- Exception while resolving variable 'forloop' in template 'admin/home.html'.
Traceback (most recent call last):
  File "/home/jn/.local/lib/python3.10/site-packages/django/template/base.py", line 829, in _resolve_lookup
    current = current[bit]
  File "/home/jn/.local/lib/python3.10/site-packages/django/template/context.py", line 83, in __getitem__
    raise KeyError(key)
KeyError: 'forloop'

During handling of the above exception, another exception occurred:

Traceback (most recent call last):
  File "/home/jn/.local/lib/python3.10/site-packages/django/template/base.py", line 835, in _resolve_lookup
    if isinstance(current, BaseContext) and getattr(type(current), bit):
AttributeError: type object 'RequestContext' has no attribute 'forloop'

During handling of the above exception, another exception occurred:

Traceback (most recent call last):
  File "/home/jn/.local/lib/python3.10/site-packages/django/template/base.py", line 843, in _resolve_lookup
    current = current[int(bit)]
ValueError: invalid literal for int() with base 10: 'forloop'

During handling of the above exception, another exception occurred:

Traceback (most recent call last):
  File "/home/jn/.local/lib/python3.10/site-packages/django/template/base.py", line 848, in _resolve_lookup
    raise VariableDoesNotExist("Failed lookup for key "
django.template.base.VariableDoesNotExist: Failed lookup for key [forloop] in [{'True': True, 'False': False, 'None': None}, {'csrf_token': <SimpleLazyObject: 'BUB4CtbTTs9d3OJFMXZIoVppXmb0PugITrnqENoNGtLqUS04SYyqUd2xD53YdjbF'>, 'request': <WSGIRequest: GET '/administrator/'>, 'user': <SimpleLazyObject: <CustomUser: System Administrator>>, 'perms': <django.contrib.auth.context_processors.PermWrapper object at 0x7f11d40b66b0>, 'messages': <django.contrib.messages.storage.fallback.FallbackStorage object at 0x7f11d4184d60>, 'DEFAULT_MESSAGE_LEVELS': {'DEBUG': 10, 'INFO': 20, 'SUCCESS': 25, 'WARNING': 30, 'ERROR': 40}, 'TITLE': '班级选举'}, {}, {'position_count': 1, 'candidate_count': 2, 'voters_count': 3, 'voted_voters_count': 3, 'positions': <QuerySet [<Position: q>]>, 'chart_data': {<Position: q>: {'candidates': ['a', 'b'], 'votes': [3, 0], 'pos_id': 1}}, 'page_title': '主页'}, {'block': <Block Node: content. Contents: [<TextNode: '\n<!-- Main content -->\n  '>, <Variable Node: 职位计数>, <TextNode: '</h3>\n              <p>职位'>, <django.template.defaulttags.URLNode object at 0x7f11ccec41c0>, <TextNode: '" class="small-box-footer'>, <Variable Node: 候选人计数>, <TextNode: '</h3>          \n         '>, <django.template.defaulttags.URLNode object at 0x7f11ccec4430>, <TextNode: '" class="small-box-footer'>, <Variable Node: 投票计数>, <TextNode: '</h3>             \n      '>, <django.template.defaulttags.URLNode object at 0x7f11ccec46a0>, <TextNode: '" class="small-box-footer'>, <Variable Node: 已投票选民计数>, <TextNode: '</h3>\n              <p>已投'>, <django.template.defaulttags.URLNode object at 0x7f11ccec4910>, <TextNode: '" class="small-box-footer'>, <django.template.defaulttags.URLNode object at 0x7f11ccec49a0>, <TextNode: '" class="btn btn-success '>, <ForNode: for position in positions, tail_len: 9>, <TextNode: '\n     '>, <IfNode>, <TextNode: '\n      </section>\n      \n'>]>}]
2024-06-09 03:51:31 django.template  /home/jn/.local/lib/python3.10/site-packages/django/template/base.py:869 base:_resolve_lookup DEBUG- Exception while resolving variable '职位计数' in template 'admin/home.html'.
Traceback (most recent call last):
  File "/home/jn/.local/lib/python3.10/site-packages/django/template/base.py", line 829, in _resolve_lookup
    current = current[bit]
  File "/home/jn/.local/lib/python3.10/site-packages/django/template/context.py", line 83, in __getitem__
    raise KeyError(key)
KeyError: '职位计数'

During handling of the above exception, another exception occurred:

Traceback (most recent call last):
  File "/home/jn/.local/lib/python3.10/site-packages/django/template/base.py", line 835, in _resolve_lookup
    if isinstance(current, BaseContext) and getattr(type(current), bit):
AttributeError: type object 'RequestContext' has no attribute '职位计数'

During handling of the above exception, another exception occurred:

Traceback (most recent call last):
  File "/home/jn/.local/lib/python3.10/site-packages/django/template/base.py", line 843, in _resolve_lookup
    current = current[int(bit)]
ValueError: invalid literal for int() with base 10: '职位计数'

During handling of the above exception, another exception occurred:

Traceback (most recent call last):
  File "/home/jn/.local/lib/python3.10/site-packages/django/template/base.py", line 848, in _resolve_lookup
    raise VariableDoesNotExist("Failed lookup for key "
django.template.base.VariableDoesNotExist: Failed lookup for key [职位计数] in [{'True': True, 'False': False, 'None': None}, {'csrf_token': <SimpleLazyObject: 'BDjVO51i7aKkfMB85iJ2WfoB5jZgQAn2Ta5hQpecUbmx6QSxbjiKsx1JL2ReepiZ'>, 'request': <WSGIRequest: GET '/administrator/'>, 'user': <SimpleLazyObject: <CustomUser: System Administrator>>, 'perms': <django.contrib.auth.context_processors.PermWrapper object at 0x7f11ccec4d60>, 'messages': <django.contrib.messages.storage.fallback.FallbackStorage object at 0x7f11d40b6740>, 'DEFAULT_MESSAGE_LEVELS': {'DEBUG': 10, 'INFO': 20, 'SUCCESS': 25, 'WARNING': 30, 'ERROR': 40}, 'TITLE': '班级选举'}, {}, {'position_count': 1, 'candidate_count': 2, 'voters_count': 2, 'voted_voters_count': 2, 'positions': <QuerySet [<Position: q>]>, 'chart_data': {<Position: q>: {'candidates': ['a', 'b'], 'votes': [2, 0], 'pos_id': 1}}, 'page_title': '主页'}, {'block': <Block Node: content. Contents: [<TextNode: '\n<!-- Main content -->\n  '>, <Variable Node: 职位计数>, <TextNode: '</h3>\n              <p>职位'>, <django.template.defaulttags.URLNode object at 0x7f11ccec7a60>, <TextNode: '" class="small-box-footer'>, <Variable Node: 候选人计数>, <TextNode: '</h3>          \n         '>, <django.template.defaulttags.URLNode object at 0x7f11ccec7850>, <TextNode: '" class="small-box-footer'>, <Variable Node: 投票计数>, <TextNode: '</h3>             \n      '>, <django.template.defaulttags.URLNode object at 0x7f11ccec6aa0>, <TextNode: '" class="small-box-footer'>, <Variable Node: 已投票选民计数>, <TextNode: '</h3>\n              <p>已投'>, <django.template.defaulttags.URLNode object at 0x7f11ccec6590>, <TextNode: '" class="small-box-footer'>, <django.template.defaulttags.URLNode object at 0x7f11ccec52d0>, <TextNode: '" class="btn btn-success '>, <ForNode: for position in positions, tail_len: 9>, <TextNode: '\n     '>, <IfNode>, <TextNode: '\n      </section>\n      \n'>]>}]
2024-06-09 03:51:31 django.template  /home/jn/.local/lib/python3.10/site-packages/django/template/base.py:869 base:_resolve_lookup DEBUG- Exception while resolving variable '候选人计数' in template 'admin/home.html'.
Traceback (most recent call last):
  File "/home/jn/.local/lib/python3.10/site-packages/django/template/base.py", line 829, in _resolve_lookup
    current = current[bit]
  File "/home/jn/.local/lib/python3.10/site-packages/django/template/context.py", line 83, in __getitem__
    raise KeyError(key)
KeyError: '候选人计数'

During handling of the above exception, another exception occurred:

Traceback (most recent call last):
  File "/home/jn/.local/lib/python3.10/site-packages/django/template/base.py", line 835, in _resolve_lookup
    if isinstance(current, BaseContext) and getattr(type(current), bit):
AttributeError: type object 'RequestContext' has no attribute '候选人计数'

During handling of the above exception, another exception occurred:

Traceback (most recent call last):
  File "/home/jn/.local/lib/python3.10/site-packages/django/template/base.py", line 843, in _resolve_lookup
    current = current[int(bit)]
ValueError: invalid literal for int() with base 10: '候选人计数'

During handling of the above exception, another exception occurred:

Traceback (most recent call last):
  File "/home/jn/.local/lib/python3.10/site-packages/django/template/base.py", line 848, in _resolve_lookup
    raise VariableDoesNotExist("Failed lookup for key "
django.template.base.VariableDoesNotExist: Failed lookup for key [候选人计数] in [{'True': True, 'False': False, 'None': None}, {'csrf_token': <SimpleLazyObject: 'BDjVO51i7aKkfMB85iJ2WfoB5jZgQAn2Ta5hQpecUbmx6QSxbjiKsx1JL2ReepiZ'>, 'request': <WSGIRequest: GET '/administrator/'>, 'user': <SimpleLazyObject: <CustomUser: System Administrator>>, 'perms': <django.contrib.auth.context_processors.PermWrapper object at 0x7f11ccec4d60>, 'messages': <django.contrib.messages.storage.fallback.FallbackStorage object at 0x7f11d40b6740>, 'DEFAULT_MESSAGE_LEVELS': {'DEBUG': 10, 'INFO': 20, 'SUCCESS': 25, 'WARNING': 30, 'ERROR': 40}, 'TITLE': '班级选举'}, {}, {'position_count': 1, 'candidate_count': 2, 'voters_count': 2, 'voted_voters_count': 2, 'positions': <QuerySet [<Position: q>]>, 'chart_data': {<Position: q>: {'candidates': ['a', 'b'], 'votes': [2, 0], 'pos_id': 1}}, 'page_title': '主页'}, {'block': <Block Node: content. Contents: [<TextNode: '\n<!-- Main content -->\n  '>, <Variable Node: 职位计数>, <TextNode: '</h3>\n              <p>职位'>, <django.template.defaulttags.URLNode object at 0x7f11ccec7a60>, <TextNode: '" class="small-box-footer'>, <Variable Node: 候选人计数>, <TextNode: '</h3>          \n         '>, <django.template.defaulttags.URLNode object at 0x7f11ccec7850>, <TextNode: '" class="small-box-footer'>, <Variable Node: 投票计数>, <TextNode: '</h3>             \n      '>, <django.template.defaulttags.URLNode object at 0x7f11ccec6aa0>, <TextNode: '" class="small-box-footer'>, <Variable Node: 已投票选民计数>, <TextNode: '</h3>\n              <p>已投'>, <django.template.defaulttags.URLNode object at 0x7f11ccec6590>, <TextNode: '" class="small-box-footer'>, <django.template.defaulttags.URLNode object at 0x7f11ccec52d0>, <TextNode: '" class="btn btn-success '>, <ForNode: for position in positions, tail_len: 9>, <TextNode: '\n     '>, <IfNode>, <TextNode: '\n      </section>\n      \n'>]>}]
2024-06-09 03:51:31 django.template  /home/jn/.local/lib/python3.10/site-packages/django/template/base.py:869 base:_resolve_lookup DEBUG- Exception while resolving variable '投票计数' in template 'admin/home.html'.
Traceback (most recent call last):
  File "/home/jn/.local/lib/python3.10/site-packages/django/template/base.py", line 829, in _resolve_lookup
    current = current[bit]
  File "/home/jn/.local/lib/python3.10/site-packages/django/template/context.py", line 83, in __getitem__
    raise KeyError(key)
KeyError: '投票计数'

During handling of the above exception, another exception occurred:

Traceback (most recent call last):
  File "/home/jn/.local/lib/python3.10/site-packages/django/template/base.py", line 835, in _resolve_lookup
    if isinstance(current, BaseContext) and getattr(type(current), bit):
AttributeError: type object 'RequestContext' has no attribute '投票计数'

During handling of the above exception, another exception occurred:

Traceback (most recent call last):
  File "/home/jn/.local/lib/python3.10/site-packages/django/template/base.py", line 843, in _resolve_lookup
    current = current[int(bit)]
ValueError: invalid literal for int() with base 10: '投票计数'

During handling of the above exception, another exception occurred:

Traceback (most recent call last):
  File "/home/jn/.local/lib/python3.10/site-packages/django/template/base.py", line 848, in _resolve_lookup
    raise VariableDoesNotExist("Failed lookup for key "
django.template.base.VariableDoesNotExist: Failed lookup for key [投票计数] in [{'True': True, 'False': False, 'None': None}, {'csrf_token': <SimpleLazyObject: 'BDjVO51i7aKkfMB85iJ2WfoB5jZgQAn2Ta5hQpecUbmx6QSxbjiKsx1JL2ReepiZ'>, 'request': <WSGIRequest: GET '/administrator/'>, 'user': <SimpleLazyObject: <CustomUser: System Administrator>>, 'perms': <django.contrib.auth.context_processors.PermWrapper object at 0x7f11ccec4d60>, 'messages': <django.contrib.messages.storage.fallback.FallbackStorage object at 0x7f11d40b6740>, 'DEFAULT_MESSAGE_LEVELS': {'DEBUG': 10, 'INFO': 20, 'SUCCESS': 25, 'WARNING': 30, 'ERROR': 40}, 'TITLE': '班级选举'}, {}, {'position_count': 1, 'candidate_count': 2, 'voters_count': 2, 'voted_voters_count': 2, 'positions': <QuerySet [<Position: q>]>, 'chart_data': {<Position: q>: {'candidates': ['a', 'b'], 'votes': [2, 0], 'pos_id': 1}}, 'page_title': '主页'}, {'block': <Block Node: content. Contents: [<TextNode: '\n<!-- Main content -->\n  '>, <Variable Node: 职位计数>, <TextNode: '</h3>\n              <p>职位'>, <django.template.defaulttags.URLNode object at 0x7f11ccec7a60>, <TextNode: '" class="small-box-footer'>, <Variable Node: 候选人计数>, <TextNode: '</h3>          \n         '>, <django.template.defaulttags.URLNode object at 0x7f11ccec7850>, <TextNode: '" class="small-box-footer'>, <Variable Node: 投票计数>, <TextNode: '</h3>             \n      '>, <django.template.defaulttags.URLNode object at 0x7f11ccec6aa0>, <TextNode: '" class="small-box-footer'>, <Variable Node: 已投票选民计数>, <TextNode: '</h3>\n              <p>已投'>, <django.template.defaulttags.URLNode object at 0x7f11ccec6590>, <TextNode: '" class="small-box-footer'>, <django.template.defaulttags.URLNode object at 0x7f11ccec52d0>, <TextNode: '" class="btn btn-success '>, <ForNode: for position in positions, tail_len: 9>, <TextNode: '\n     '>, <IfNode>, <TextNode: '\n      </section>\n      \n'>]>}]
2024-06-09 03:51:31 django.template  /home/jn/.local/lib/python3.10/site-packages/django/template/base.py:869 base:_resolve_lookup DEBUG- Exception while resolving variable '已投票选民计数' in template 'admin/home.html'.
Traceback (most recent call last):
  File "/home/jn/.local/lib/python3.10/site-packages/django/template/base.py", line 829, in _resolve_lookup
    current = current[bit]
  File "/home/jn/.local/lib/python3.10/site-packages/django/template/context.py", line 83, in __getitem__
    raise KeyError(key)
KeyError: '已投票选民计数'

During handling of the above exception, another exception occurred:

Traceback (most recent call last):
  File "/home/jn/.local/lib/python3.10/site-packages/django/template/base.py", line 835, in _resolve_lookup
    if isinstance(current, BaseContext) and getattr(type(current), bit):
AttributeError: type object 'RequestContext' has no attribute '已投票选民计数'

During handling of the above exception, another exception occurred:

Traceback (most recent call last):
  File "/home/jn/.local/lib/python3.10/site-packages/django/template/base.py", line 843, in _resolve_lookup
    current = current[int(bit)]
ValueError: invalid literal for int() with base 10: '已投票选民计数'

During handling of the above exception, another exception occurred:

Traceback (most recent call last):
  File "/home/jn/.local/lib/python3.10/site-packages/django/template/base.py", line 848, in _resolve_lookup
    raise VariableDoesNotExist("Failed lookup for key "
django.template.base.VariableDoesNotExist: Failed lookup for key [已投票选民计数] in [{'True': True, 'False': False, 'None': None}, {'csrf_token': <SimpleLazyObject: 'BDjVO51i7aKkfMB85iJ2WfoB5jZgQAn2Ta5hQpecUbmx6QSxbjiKsx1JL2ReepiZ'>, 'request': <WSGIRequest: GET '/administrator/'>, 'user': <SimpleLazyObject: <CustomUser: System Administrator>>, 'perms': <django.contrib.auth.context_processors.PermWrapper object at 0x7f11ccec4d60>, 'messages': <django.contrib.messages.storage.fallback.FallbackStorage object at 0x7f11d40b6740>, 'DEFAULT_MESSAGE_LEVELS': {'DEBUG': 10, 'INFO': 20, 'SUCCESS': 25, 'WARNING': 30, 'ERROR': 40}, 'TITLE': '班级选举'}, {}, {'position_count': 1, 'candidate_count': 2, 'voters_count': 2, 'voted_voters_count': 2, 'positions': <QuerySet [<Position: q>]>, 'chart_data': {<Position: q>: {'candidates': ['a', 'b'], 'votes': [2, 0], 'pos_id': 1}}, 'page_title': '主页'}, {'block': <Block Node: content. Contents: [<TextNode: '\n<!-- Main content -->\n  '>, <Variable Node: 职位计数>, <TextNode: '</h3>\n              <p>职位'>, <django.template.defaulttags.URLNode object at 0x7f11ccec7a60>, <TextNode: '" class="small-box-footer'>, <Variable Node: 候选人计数>, <TextNode: '</h3>          \n         '>, <django.template.defaulttags.URLNode object at 0x7f11ccec7850>, <TextNode: '" class="small-box-footer'>, <Variable Node: 投票计数>, <TextNode: '</h3>             \n      '>, <django.template.defaulttags.URLNode object at 0x7f11ccec6aa0>, <TextNode: '" class="small-box-footer'>, <Variable Node: 已投票选民计数>, <TextNode: '</h3>\n              <p>已投'>, <django.template.defaulttags.URLNode object at 0x7f11ccec6590>, <TextNode: '" class="small-box-footer'>, <django.template.defaulttags.URLNode object at 0x7f11ccec52d0>, <TextNode: '" class="btn btn-success '>, <ForNode: for position in positions, tail_len: 9>, <TextNode: '\n     '>, <IfNode>, <TextNode: '\n      </section>\n      \n'>]>}]
2024-06-09 03:51:31 django.template  /home/jn/.local/lib/python3.10/site-packages/django/template/base.py:869 base:_resolve_lookup DEBUG- Exception while resolving variable 'forloop' in template 'admin/home.html'.
Traceback (most recent call last):
  File "/home/jn/.local/lib/python3.10/site-packages/django/template/base.py", line 829, in _resolve_lookup
    current = current[bit]
  File "/home/jn/.local/lib/python3.10/site-packages/django/template/context.py", line 83, in __getitem__
    raise KeyError(key)
KeyError: 'forloop'

During handling of the above exception, another exception occurred:

Traceback (most recent call last):
  File "/home/jn/.local/lib/python3.10/site-packages/django/template/base.py", line 835, in _resolve_lookup
    if isinstance(current, BaseContext) and getattr(type(current), bit):
AttributeError: type object 'RequestContext' has no attribute 'forloop'

During handling of the above exception, another exception occurred:

Traceback (most recent call last):
  File "/home/jn/.local/lib/python3.10/site-packages/django/template/base.py", line 843, in _resolve_lookup
    current = current[int(bit)]
ValueError: invalid literal for int() with base 10: 'forloop'

During handling of the above exception, another exception occurred:

Traceback (most recent call last):
  File "/home/jn/.local/lib/python3.10/site-packages/django/template/base.py", line 848, in _resolve_lookup
    raise VariableDoesNotExist("Failed lookup for key "
django.template.base.VariableDoesNotExist: Failed lookup for key [forloop] in [{'True': True, 'False': False, 'None': None}, {'csrf_token': <SimpleLazyObject: 'BDjVO51i7aKkfMB85iJ2WfoB5jZgQAn2Ta5hQpecUbmx6QSxbjiKsx1JL2ReepiZ'>, 'request': <WSGIRequest: GET '/administrator/'>, 'user': <SimpleLazyObject: <CustomUser: System Administrator>>, 'perms': <django.contrib.auth.context_processors.PermWrapper object at 0x7f11ccec4d60>, 'messages': <django.contrib.messages.storage.fallback.FallbackStorage object at 0x7f11d40b6740>, 'DEFAULT_MESSAGE_LEVELS': {'DEBUG': 10, 'INFO': 20, 'SUCCESS': 25, 'WARNING': 30, 'ERROR': 40}, 'TITLE': '班级选举'}, {}, {'position_count': 1, 'candidate_count': 2, 'voters_count': 2, 'voted_voters_count': 2, 'positions': <QuerySet [<Position: q>]>, 'chart_data': {<Position: q>: {'candidates': ['a', 'b'], 'votes': [2, 0], 'pos_id': 1}}, 'page_title': '主页'}, {'block': <Block Node: content. Contents: [<TextNode: '\n<!-- Main content -->\n  '>, <Variable Node: 职位计数>, <TextNode: '</h3>\n              <p>职位'>, <django.template.defaulttags.URLNode object at 0x7f11ccec7a60>, <TextNode: '" class="small-box-footer'>, <Variable Node: 候选人计数>, <TextNode: '</h3>          \n         '>, <django.template.defaulttags.URLNode object at 0x7f11ccec7850>, <TextNode: '" class="small-box-footer'>, <Variable Node: 投票计数>, <TextNode: '</h3>             \n      '>, <django.template.defaulttags.URLNode object at 0x7f11ccec6aa0>, <TextNode: '" class="small-box-footer'>, <Variable Node: 已投票选民计数>, <TextNode: '</h3>\n              <p>已投'>, <django.template.defaulttags.URLNode object at 0x7f11ccec6590>, <TextNode: '" class="small-box-footer'>, <django.template.defaulttags.URLNode object at 0x7f11ccec52d0>, <TextNode: '" class="btn btn-success '>, <ForNode: for position in positions, tail_len: 9>, <TextNode: '\n     '>, <IfNode>, <TextNode: '\n      </section>\n      \n'>]>}]
2024-06-09 03:53:41 django.template  /home/jn/.local/lib/python3.10/site-packages/django/template/base.py:869 base:_resolve_lookup DEBUG- Exception while resolving variable 'page_title' in template 'voting/voter/ballot.html'.
Traceback (most recent call last):
  File "/home/jn/.local/lib/python3.10/site-packages/django/template/base.py", line 829, in _resolve_lookup
    current = current[bit]
  File "/home/jn/.local/lib/python3.10/site-packages/django/template/context.py", line 83, in __getitem__
    raise KeyError(key)
KeyError: 'page_title'

During handling of the above exception, another exception occurred:

Traceback (most recent call last):
  File "/home/jn/.local/lib/python3.10/site-packages/django/template/base.py", line 835, in _resolve_lookup
    if isinstance(current, BaseContext) and getattr(type(current), bit):
AttributeError: type object 'RequestContext' has no attribute 'page_title'

During handling of the above exception, another exception occurred:

Traceback (most recent call last):
  File "/home/jn/.local/lib/python3.10/site-packages/django/template/base.py", line 843, in _resolve_lookup
    current = current[int(bit)]
ValueError: invalid literal for int() with base 10: 'page_title'

During handling of the above exception, another exception occurred:

Traceback (most recent call last):
  File "/home/jn/.local/lib/python3.10/site-packages/django/template/base.py", line 848, in _resolve_lookup
    raise VariableDoesNotExist("Failed lookup for key "
django.template.base.VariableDoesNotExist: Failed lookup for key [page_title] in [{'True': True, 'False': False, 'None': None}, {'csrf_token': <SimpleLazyObject: 'eeSS0v9ESFcE4oCqsVnWIP5fs04OqGCBBOMYkhd8aZ9DDkUZeCfMC67gqu7FEbeA'>, 'request': <WSGIRequest: GET '/voting/ballot/vote'>, 'user': <SimpleLazyObject: <CustomUser: 橙 子>>, 'perms': <django.contrib.auth.context_processors.PermWrapper object at 0x7f8a1e4da4d0>, 'messages': <django.contrib.messages.storage.fallback.FallbackStorage object at 0x7f8a1f525b10>, 'DEFAULT_MESSAGE_LEVELS': {'DEBUG': 10, 'INFO': 20, 'SUCCESS': 25, 'WARNING': 30, 'ERROR': 40}, 'TITLE': '班级选举'}, {}, {'ballot': '<div class="row">\t<div class="col-xs-12"><div class="box box-solid" id="1">\n             <div class="box-header with-border">\n            <h3 class="box-title"><b>q</b></h3></div>\n        <div class="box-body">\n        <p>你最多可以选 10 名候选人\n        <span class="pull-right">\n        <button type="button" class="btn btn-success btn-sm btn-flat reset" data-desc="q"><i class="fa fa-refresh"></i> 重置</button>\n        </span>\n        </p>\n        <div id="candidate_list">\n        <ul>\n        <li><input type="checkbox" value="2" class="flat-red q" name="q[]"><button type="button" class="btn btn-primary btn-sm btn-flat clist platform" data-fullname="a" data-bio="aa"><i class="fa fa-search"></i> 简介</button><img src="/media/candidates/头像_Xh0zk01.JPG" height="100px" width="100px" class="clist"><span class="cname clist">a</span></li><li><input type="checkbox" value="3" class="flat-red q" name="q[]"><button type="button" class="btn btn-primary btn-sm btn-flat clist platform" data-fullname="b" data-bio="bb"><i class="fa fa-search"></i> 简介</button><img src="/media/candidates/头像_CJQ1BJs.JPG" height="100px" width="100px" class="clist"><span class="cname clist">b</span></li>\n        </ul>\n        </div>\n        </div>\n        </div>\n        </div>\n        </div>\n        '}]
2024-06-09 03:53:41 django.template  /home/jn/.local/lib/python3.10/site-packages/django/template/base.py:869 base:_resolve_lookup DEBUG- Exception while resolving variable 'page_title' in template 'voting/voter/ballot.html'.
Traceback (most recent call last):
  File "/home/jn/.local/lib/python3.10/site-packages/django/template/base.py", line 829, in _resolve_lookup
    current = current[bit]
  File "/home/jn/.local/lib/python3.10/site-packages/django/template/context.py", line 83, in __getitem__
    raise KeyError(key)
KeyError: 'page_title'

During handling of the above exception, another exception occurred:

Traceback (most recent call last):
  File "/home/jn/.local/lib/python3.10/site-packages/django/template/base.py", line 835, in _resolve_lookup
    if isinstance(current, BaseContext) and getattr(type(current), bit):
AttributeError: type object 'RequestContext' has no attribute 'page_title'

During handling of the above exception, another exception occurred:

Traceback (most recent call last):
  File "/home/jn/.local/lib/python3.10/site-packages/django/template/base.py", line 843, in _resolve_lookup
    current = current[int(bit)]
ValueError: invalid literal for int() with base 10: 'page_title'

During handling of the above exception, another exception occurred:

Traceback (most recent call last):
  File "/home/jn/.local/lib/python3.10/site-packages/django/template/base.py", line 848, in _resolve_lookup
    raise VariableDoesNotExist("Failed lookup for key "
django.template.base.VariableDoesNotExist: Failed lookup for key [page_title] in [{'True': True, 'False': False, 'None': None}, {'csrf_token': <SimpleLazyObject: 'eeSS0v9ESFcE4oCqsVnWIP5fs04OqGCBBOMYkhd8aZ9DDkUZeCfMC67gqu7FEbeA'>, 'request': <WSGIRequest: GET '/voting/ballot/vote'>, 'user': <SimpleLazyObject: <CustomUser: 橙 子>>, 'perms': <django.contrib.auth.context_processors.PermWrapper object at 0x7f8a1e4da4d0>, 'messages': <django.contrib.messages.storage.fallback.FallbackStorage object at 0x7f8a1f525b10>, 'DEFAULT_MESSAGE_LEVELS': {'DEBUG': 10, 'INFO': 20, 'SUCCESS': 25, 'WARNING': 30, 'ERROR': 40}, 'TITLE': '班级选举'}, {}, {'ballot': '<div class="row">\t<div class="col-xs-12"><div class="box box-solid" id="1">\n             <div class="box-header with-border">\n            <h3 class="box-title"><b>q</b></h3></div>\n        <div class="box-body">\n        <p>你最多可以选 10 名候选人\n        <span class="pull-right">\n        <button type="button" class="btn btn-success btn-sm btn-flat reset" data-desc="q"><i class="fa fa-refresh"></i> 重置</button>\n        </span>\n        </p>\n        <div id="candidate_list">\n        <ul>\n        <li><input type="checkbox" value="2" class="flat-red q" name="q[]"><button type="button" class="btn btn-primary btn-sm btn-flat clist platform" data-fullname="a" data-bio="aa"><i class="fa fa-search"></i> 简介</button><img src="/media/candidates/头像_Xh0zk01.JPG" height="100px" width="100px" class="clist"><span class="cname clist">a</span></li><li><input type="checkbox" value="3" class="flat-red q" name="q[]"><button type="button" class="btn btn-primary btn-sm btn-flat clist platform" data-fullname="b" data-bio="bb"><i class="fa fa-search"></i> 简介</button><img src="/media/candidates/头像_CJQ1BJs.JPG" height="100px" width="100px" class="clist"><span class="cname clist">b</span></li>\n        </ul>\n        </div>\n        </div>\n        </div>\n        </div>\n        </div>\n        '}]
2024-06-09 03:54:29 django.template  /home/jn/.local/lib/python3.10/site-packages/django/template/base.py:869 base:_resolve_lookup DEBUG- Exception while resolving variable 'page_title' in template 'voting/voter/result.html'.
Traceback (most recent call last):
  File "/home/jn/.local/lib/python3.10/site-packages/django/template/base.py", line 829, in _resolve_lookup
    current = current[bit]
  File "/home/jn/.local/lib/python3.10/site-packages/django/template/context.py", line 83, in __getitem__
    raise KeyError(key)
KeyError: 'page_title'

During handling of the above exception, another exception occurred:

Traceback (most recent call last):
  File "/home/jn/.local/lib/python3.10/site-packages/django/template/base.py", line 835, in _resolve_lookup
    if isinstance(current, BaseContext) and getattr(type(current), bit):
AttributeError: type object 'RequestContext' has no attribute 'page_title'

During handling of the above exception, another exception occurred:

Traceback (most recent call last):
  File "/home/jn/.local/lib/python3.10/site-packages/django/template/base.py", line 843, in _resolve_lookup
    current = current[int(bit)]
ValueError: invalid literal for int() with base 10: 'page_title'

During handling of the above exception, another exception occurred:

Traceback (most recent call last):
  File "/home/jn/.local/lib/python3.10/site-packages/django/template/base.py", line 848, in _resolve_lookup
    raise VariableDoesNotExist("Failed lookup for key "
django.template.base.VariableDoesNotExist: Failed lookup for key [page_title] in [{'True': True, 'False': False, 'None': None}, {'csrf_token': <SimpleLazyObject: 'GggirkrKZyQS7kwmkTwbNfcSRgAxsGb03QaoL6vehSNRGgOV6Ao1HweTPKDoGbNZ'>, 'request': <WSGIRequest: GET '/voting/dashboard/'>, 'user': <SimpleLazyObject: <CustomUser: 橙 子>>, 'perms': <django.contrib.auth.context_processors.PermWrapper object at 0x7f8a1e4db910>, 'messages': <django.contrib.messages.storage.fallback.FallbackStorage object at 0x7f8a1f5874c0>, 'DEFAULT_MESSAGE_LEVELS': {'DEBUG': 10, 'INFO': 20, 'SUCCESS': 25, 'WARNING': 30, 'ERROR': 40}, 'TITLE': '班级选举'}, {}, {'my_votes': <QuerySet [<Votes: Votes object (4)>]>}]
2024-06-09 03:54:29 django.template  /home/jn/.local/lib/python3.10/site-packages/django/template/base.py:869 base:_resolve_lookup DEBUG- Exception while resolving variable 'page_title' in template 'voting/voter/result.html'.
Traceback (most recent call last):
  File "/home/jn/.local/lib/python3.10/site-packages/django/template/base.py", line 829, in _resolve_lookup
    current = current[bit]
  File "/home/jn/.local/lib/python3.10/site-packages/django/template/context.py", line 83, in __getitem__
    raise KeyError(key)
KeyError: 'page_title'

During handling of the above exception, another exception occurred:

Traceback (most recent call last):
  File "/home/jn/.local/lib/python3.10/site-packages/django/template/base.py", line 835, in _resolve_lookup
    if isinstance(current, BaseContext) and getattr(type(current), bit):
AttributeError: type object 'RequestContext' has no attribute 'page_title'

During handling of the above exception, another exception occurred:

Traceback (most recent call last):
  File "/home/jn/.local/lib/python3.10/site-packages/django/template/base.py", line 843, in _resolve_lookup
    current = current[int(bit)]
ValueError: invalid literal for int() with base 10: 'page_title'

During handling of the above exception, another exception occurred:

Traceback (most recent call last):
  File "/home/jn/.local/lib/python3.10/site-packages/django/template/base.py", line 848, in _resolve_lookup
    raise VariableDoesNotExist("Failed lookup for key "
django.template.base.VariableDoesNotExist: Failed lookup for key [page_title] in [{'True': True, 'False': False, 'None': None}, {'csrf_token': <SimpleLazyObject: 'GggirkrKZyQS7kwmkTwbNfcSRgAxsGb03QaoL6vehSNRGgOV6Ao1HweTPKDoGbNZ'>, 'request': <WSGIRequest: GET '/voting/dashboard/'>, 'user': <SimpleLazyObject: <CustomUser: 橙 子>>, 'perms': <django.contrib.auth.context_processors.PermWrapper object at 0x7f8a1e4db910>, 'messages': <django.contrib.messages.storage.fallback.FallbackStorage object at 0x7f8a1f5874c0>, 'DEFAULT_MESSAGE_LEVELS': {'DEBUG': 10, 'INFO': 20, 'SUCCESS': 25, 'WARNING': 30, 'ERROR': 40}, 'TITLE': '班级选举'}, {}, {'my_votes': <QuerySet [<Votes: Votes object (4)>]>}]
2024-06-09 03:54:53 django.template  /home/jn/.local/lib/python3.10/site-packages/django/template/base.py:869 base:_resolve_lookup DEBUG- Exception while resolving variable '职位计数' in template 'admin/home.html'.
Traceback (most recent call last):
  File "/home/jn/.local/lib/python3.10/site-packages/django/template/base.py", line 829, in _resolve_lookup
    current = current[bit]
  File "/home/jn/.local/lib/python3.10/site-packages/django/template/context.py", line 83, in __getitem__
    raise KeyError(key)
KeyError: '职位计数'

During handling of the above exception, another exception occurred:

Traceback (most recent call last):
  File "/home/jn/.local/lib/python3.10/site-packages/django/template/base.py", line 835, in _resolve_lookup
    if isinstance(current, BaseContext) and getattr(type(current), bit):
AttributeError: type object 'RequestContext' has no attribute '职位计数'

During handling of the above exception, another exception occurred:

Traceback (most recent call last):
  File "/home/jn/.local/lib/python3.10/site-packages/django/template/base.py", line 843, in _resolve_lookup
    current = current[int(bit)]
ValueError: invalid literal for int() with base 10: '职位计数'

During handling of the above exception, another exception occurred:

Traceback (most recent call last):
  File "/home/jn/.local/lib/python3.10/site-packages/django/template/base.py", line 848, in _resolve_lookup
    raise VariableDoesNotExist("Failed lookup for key "
django.template.base.VariableDoesNotExist: Failed lookup for key [职位计数] in [{'True': True, 'False': False, 'None': None}, {'csrf_token': <SimpleLazyObject: 'ZlqbVR8nS59oiqzvvUTwjLzmnrEb6NETBd5e8Sf6JRUd4tvjl2N9TJDNFns4ozZB'>, 'request': <WSGIRequest: GET '/administrator/'>, 'user': <SimpleLazyObject: <CustomUser: System Administrator>>, 'perms': <django.contrib.auth.context_processors.PermWrapper object at 0x7f8a1e4db5e0>, 'messages': <django.contrib.messages.storage.fallback.FallbackStorage object at 0x7f8a1e4f89d0>, 'DEFAULT_MESSAGE_LEVELS': {'DEBUG': 10, 'INFO': 20, 'SUCCESS': 25, 'WARNING': 30, 'ERROR': 40}, 'TITLE': '班级选举'}, {}, {'position_count': 1, 'candidate_count': 2, 'voters_count': 3, 'voted_voters_count': 3, 'positions': <QuerySet [<Position: q>]>, 'chart_data': {<Position: q>: {'candidates': ['a', 'b'], 'votes': [3, 0], 'pos_id': 1}}, 'page_title': '主页'}, {'block': <Block Node: content. Contents: [<TextNode: '\n<!-- Main content -->\n  '>, <Variable Node: 职位计数>, <TextNode: '</h3>\n              <p>职位'>, <django.template.defaulttags.URLNode object at 0x7f8a1e4fbd60>, <TextNode: '" class="small-box-footer'>, <Variable Node: 候选人计数>, <TextNode: '</h3>          \n         '>, <django.template.defaulttags.URLNode object at 0x7f8a1e4f9060>, <TextNode: '" class="small-box-footer'>, <Variable Node: 投票计数>, <TextNode: '</h3>             \n      '>, <django.template.defaulttags.URLNode object at 0x7f8a1f5c4310>, <TextNode: '" class="small-box-footer'>, <Variable Node: 已投票选民计数>, <TextNode: '</h3>\n              <p>已投'>, <django.template.defaulttags.URLNode object at 0x7f8a1e483bb0>, <TextNode: '" class="small-box-footer'>, <django.template.defaulttags.URLNode object at 0x7f8a1e483280>, <TextNode: '" class="btn btn-success '>, <ForNode: for position in positions, tail_len: 9>, <TextNode: '\n     '>, <IfNode>, <TextNode: '\n      </section>\n      \n'>]>}]
2024-06-09 03:54:53 django.template  /home/jn/.local/lib/python3.10/site-packages/django/template/base.py:869 base:_resolve_lookup DEBUG- Exception while resolving variable '候选人计数' in template 'admin/home.html'.
Traceback (most recent call last):
  File "/home/jn/.local/lib/python3.10/site-packages/django/template/base.py", line 829, in _resolve_lookup
    current = current[bit]
  File "/home/jn/.local/lib/python3.10/site-packages/django/template/context.py", line 83, in __getitem__
    raise KeyError(key)
KeyError: '候选人计数'

During handling of the above exception, another exception occurred:

Traceback (most recent call last):
  File "/home/jn/.local/lib/python3.10/site-packages/django/template/base.py", line 835, in _resolve_lookup
    if isinstance(current, BaseContext) and getattr(type(current), bit):
AttributeError: type object 'RequestContext' has no attribute '候选人计数'

During handling of the above exception, another exception occurred:

Traceback (most recent call last):
  File "/home/jn/.local/lib/python3.10/site-packages/django/template/base.py", line 843, in _resolve_lookup
    current = current[int(bit)]
ValueError: invalid literal for int() with base 10: '候选人计数'

During handling of the above exception, another exception occurred:

Traceback (most recent call last):
  File "/home/jn/.local/lib/python3.10/site-packages/django/template/base.py", line 848, in _resolve_lookup
    raise VariableDoesNotExist("Failed lookup for key "
django.template.base.VariableDoesNotExist: Failed lookup for key [候选人计数] in [{'True': True, 'False': False, 'None': None}, {'csrf_token': <SimpleLazyObject: 'ZlqbVR8nS59oiqzvvUTwjLzmnrEb6NETBd5e8Sf6JRUd4tvjl2N9TJDNFns4ozZB'>, 'request': <WSGIRequest: GET '/administrator/'>, 'user': <SimpleLazyObject: <CustomUser: System Administrator>>, 'perms': <django.contrib.auth.context_processors.PermWrapper object at 0x7f8a1e4db5e0>, 'messages': <django.contrib.messages.storage.fallback.FallbackStorage object at 0x7f8a1e4f89d0>, 'DEFAULT_MESSAGE_LEVELS': {'DEBUG': 10, 'INFO': 20, 'SUCCESS': 25, 'WARNING': 30, 'ERROR': 40}, 'TITLE': '班级选举'}, {}, {'position_count': 1, 'candidate_count': 2, 'voters_count': 3, 'voted_voters_count': 3, 'positions': <QuerySet [<Position: q>]>, 'chart_data': {<Position: q>: {'candidates': ['a', 'b'], 'votes': [3, 0], 'pos_id': 1}}, 'page_title': '主页'}, {'block': <Block Node: content. Contents: [<TextNode: '\n<!-- Main content -->\n  '>, <Variable Node: 职位计数>, <TextNode: '</h3>\n              <p>职位'>, <django.template.defaulttags.URLNode object at 0x7f8a1e4fbd60>, <TextNode: '" class="small-box-footer'>, <Variable Node: 候选人计数>, <TextNode: '</h3>          \n         '>, <django.template.defaulttags.URLNode object at 0x7f8a1e4f9060>, <TextNode: '" class="small-box-footer'>, <Variable Node: 投票计数>, <TextNode: '</h3>             \n      '>, <django.template.defaulttags.URLNode object at 0x7f8a1f5c4310>, <TextNode: '" class="small-box-footer'>, <Variable Node: 已投票选民计数>, <TextNode: '</h3>\n              <p>已投'>, <django.template.defaulttags.URLNode object at 0x7f8a1e483bb0>, <TextNode: '" class="small-box-footer'>, <django.template.defaulttags.URLNode object at 0x7f8a1e483280>, <TextNode: '" class="btn btn-success '>, <ForNode: for position in positions, tail_len: 9>, <TextNode: '\n     '>, <IfNode>, <TextNode: '\n      </section>\n      \n'>]>}]
2024-06-09 03:54:53 django.template  /home/jn/.local/lib/python3.10/site-packages/django/template/base.py:869 base:_resolve_lookup DEBUG- Exception while resolving variable '投票计数' in template 'admin/home.html'.
Traceback (most recent call last):
  File "/home/jn/.local/lib/python3.10/site-packages/django/template/base.py", line 829, in _resolve_lookup
    current = current[bit]
  File "/home/jn/.local/lib/python3.10/site-packages/django/template/context.py", line 83, in __getitem__
    raise KeyError(key)
KeyError: '投票计数'

During handling of the above exception, another exception occurred:

Traceback (most recent call last):
  File "/home/jn/.local/lib/python3.10/site-packages/django/template/base.py", line 835, in _resolve_lookup
    if isinstance(current, BaseContext) and getattr(type(current), bit):
AttributeError: type object 'RequestContext' has no attribute '投票计数'

During handling of the above exception, another exception occurred:

Traceback (most recent call last):
  File "/home/jn/.local/lib/python3.10/site-packages/django/template/base.py", line 843, in _resolve_lookup
    current = current[int(bit)]
ValueError: invalid literal for int() with base 10: '投票计数'

During handling of the above exception, another exception occurred:

Traceback (most recent call last):
  File "/home/jn/.local/lib/python3.10/site-packages/django/template/base.py", line 848, in _resolve_lookup
    raise VariableDoesNotExist("Failed lookup for key "
django.template.base.VariableDoesNotExist: Failed lookup for key [投票计数] in [{'True': True, 'False': False, 'None': None}, {'csrf_token': <SimpleLazyObject: 'ZlqbVR8nS59oiqzvvUTwjLzmnrEb6NETBd5e8Sf6JRUd4tvjl2N9TJDNFns4ozZB'>, 'request': <WSGIRequest: GET '/administrator/'>, 'user': <SimpleLazyObject: <CustomUser: System Administrator>>, 'perms': <django.contrib.auth.context_processors.PermWrapper object at 0x7f8a1e4db5e0>, 'messages': <django.contrib.messages.storage.fallback.FallbackStorage object at 0x7f8a1e4f89d0>, 'DEFAULT_MESSAGE_LEVELS': {'DEBUG': 10, 'INFO': 20, 'SUCCESS': 25, 'WARNING': 30, 'ERROR': 40}, 'TITLE': '班级选举'}, {}, {'position_count': 1, 'candidate_count': 2, 'voters_count': 3, 'voted_voters_count': 3, 'positions': <QuerySet [<Position: q>]>, 'chart_data': {<Position: q>: {'candidates': ['a', 'b'], 'votes': [3, 0], 'pos_id': 1}}, 'page_title': '主页'}, {'block': <Block Node: content. Contents: [<TextNode: '\n<!-- Main content -->\n  '>, <Variable Node: 职位计数>, <TextNode: '</h3>\n              <p>职位'>, <django.template.defaulttags.URLNode object at 0x7f8a1e4fbd60>, <TextNode: '" class="small-box-footer'>, <Variable Node: 候选人计数>, <TextNode: '</h3>          \n         '>, <django.template.defaulttags.URLNode object at 0x7f8a1e4f9060>, <TextNode: '" class="small-box-footer'>, <Variable Node: 投票计数>, <TextNode: '</h3>             \n      '>, <django.template.defaulttags.URLNode object at 0x7f8a1f5c4310>, <TextNode: '" class="small-box-footer'>, <Variable Node: 已投票选民计数>, <TextNode: '</h3>\n              <p>已投'>, <django.template.defaulttags.URLNode object at 0x7f8a1e483bb0>, <TextNode: '" class="small-box-footer'>, <django.template.defaulttags.URLNode object at 0x7f8a1e483280>, <TextNode: '" class="btn btn-success '>, <ForNode: for position in positions, tail_len: 9>, <TextNode: '\n     '>, <IfNode>, <TextNode: '\n      </section>\n      \n'>]>}]
2024-06-09 03:54:53 django.template  /home/jn/.local/lib/python3.10/site-packages/django/template/base.py:869 base:_resolve_lookup DEBUG- Exception while resolving variable '已投票选民计数' in template 'admin/home.html'.
Traceback (most recent call last):
  File "/home/jn/.local/lib/python3.10/site-packages/django/template/base.py", line 829, in _resolve_lookup
    current = current[bit]
  File "/home/jn/.local/lib/python3.10/site-packages/django/template/context.py", line 83, in __getitem__
    raise KeyError(key)
KeyError: '已投票选民计数'

During handling of the above exception, another exception occurred:

Traceback (most recent call last):
  File "/home/jn/.local/lib/python3.10/site-packages/django/template/base.py", line 835, in _resolve_lookup
    if isinstance(current, BaseContext) and getattr(type(current), bit):
AttributeError: type object 'RequestContext' has no attribute '已投票选民计数'

During handling of the above exception, another exception occurred:

Traceback (most recent call last):
  File "/home/jn/.local/lib/python3.10/site-packages/django/template/base.py", line 843, in _resolve_lookup
    current = current[int(bit)]
ValueError: invalid literal for int() with base 10: '已投票选民计数'

During handling of the above exception, another exception occurred:

Traceback (most recent call last):
  File "/home/jn/.local/lib/python3.10/site-packages/django/template/base.py", line 848, in _resolve_lookup
    raise VariableDoesNotExist("Failed lookup for key "
django.template.base.VariableDoesNotExist: Failed lookup for key [已投票选民计数] in [{'True': True, 'False': False, 'None': None}, {'csrf_token': <SimpleLazyObject: 'ZlqbVR8nS59oiqzvvUTwjLzmnrEb6NETBd5e8Sf6JRUd4tvjl2N9TJDNFns4ozZB'>, 'request': <WSGIRequest: GET '/administrator/'>, 'user': <SimpleLazyObject: <CustomUser: System Administrator>>, 'perms': <django.contrib.auth.context_processors.PermWrapper object at 0x7f8a1e4db5e0>, 'messages': <django.contrib.messages.storage.fallback.FallbackStorage object at 0x7f8a1e4f89d0>, 'DEFAULT_MESSAGE_LEVELS': {'DEBUG': 10, 'INFO': 20, 'SUCCESS': 25, 'WARNING': 30, 'ERROR': 40}, 'TITLE': '班级选举'}, {}, {'position_count': 1, 'candidate_count': 2, 'voters_count': 3, 'voted_voters_count': 3, 'positions': <QuerySet [<Position: q>]>, 'chart_data': {<Position: q>: {'candidates': ['a', 'b'], 'votes': [3, 0], 'pos_id': 1}}, 'page_title': '主页'}, {'block': <Block Node: content. Contents: [<TextNode: '\n<!-- Main content -->\n  '>, <Variable Node: 职位计数>, <TextNode: '</h3>\n              <p>职位'>, <django.template.defaulttags.URLNode object at 0x7f8a1e4fbd60>, <TextNode: '" class="small-box-footer'>, <Variable Node: 候选人计数>, <TextNode: '</h3>          \n         '>, <django.template.defaulttags.URLNode object at 0x7f8a1e4f9060>, <TextNode: '" class="small-box-footer'>, <Variable Node: 投票计数>, <TextNode: '</h3>             \n      '>, <django.template.defaulttags.URLNode object at 0x7f8a1f5c4310>, <TextNode: '" class="small-box-footer'>, <Variable Node: 已投票选民计数>, <TextNode: '</h3>\n              <p>已投'>, <django.template.defaulttags.URLNode object at 0x7f8a1e483bb0>, <TextNode: '" class="small-box-footer'>, <django.template.defaulttags.URLNode object at 0x7f8a1e483280>, <TextNode: '" class="btn btn-success '>, <ForNode: for position in positions, tail_len: 9>, <TextNode: '\n     '>, <IfNode>, <TextNode: '\n      </section>\n      \n'>]>}]
2024-06-09 03:54:53 django.template  /home/jn/.local/lib/python3.10/site-packages/django/template/base.py:869 base:_resolve_lookup DEBUG- Exception while resolving variable 'forloop' in template 'admin/home.html'.
Traceback (most recent call last):
  File "/home/jn/.local/lib/python3.10/site-packages/django/template/base.py", line 829, in _resolve_lookup
    current = current[bit]
  File "/home/jn/.local/lib/python3.10/site-packages/django/template/context.py", line 83, in __getitem__
    raise KeyError(key)
KeyError: 'forloop'

During handling of the above exception, another exception occurred:

Traceback (most recent call last):
  File "/home/jn/.local/lib/python3.10/site-packages/django/template/base.py", line 835, in _resolve_lookup
    if isinstance(current, BaseContext) and getattr(type(current), bit):
AttributeError: type object 'RequestContext' has no attribute 'forloop'

During handling of the above exception, another exception occurred:

Traceback (most recent call last):
  File "/home/jn/.local/lib/python3.10/site-packages/django/template/base.py", line 843, in _resolve_lookup
    current = current[int(bit)]
ValueError: invalid literal for int() with base 10: 'forloop'

During handling of the above exception, another exception occurred:

Traceback (most recent call last):
  File "/home/jn/.local/lib/python3.10/site-packages/django/template/base.py", line 848, in _resolve_lookup
    raise VariableDoesNotExist("Failed lookup for key "
django.template.base.VariableDoesNotExist: Failed lookup for key [forloop] in [{'True': True, 'False': False, 'None': None}, {'csrf_token': <SimpleLazyObject: 'ZlqbVR8nS59oiqzvvUTwjLzmnrEb6NETBd5e8Sf6JRUd4tvjl2N9TJDNFns4ozZB'>, 'request': <WSGIRequest: GET '/administrator/'>, 'user': <SimpleLazyObject: <CustomUser: System Administrator>>, 'perms': <django.contrib.auth.context_processors.PermWrapper object at 0x7f8a1e4db5e0>, 'messages': <django.contrib.messages.storage.fallback.FallbackStorage object at 0x7f8a1e4f89d0>, 'DEFAULT_MESSAGE_LEVELS': {'DEBUG': 10, 'INFO': 20, 'SUCCESS': 25, 'WARNING': 30, 'ERROR': 40}, 'TITLE': '班级选举'}, {}, {'position_count': 1, 'candidate_count': 2, 'voters_count': 3, 'voted_voters_count': 3, 'positions': <QuerySet [<Position: q>]>, 'chart_data': {<Position: q>: {'candidates': ['a', 'b'], 'votes': [3, 0], 'pos_id': 1}}, 'page_title': '主页'}, {'block': <Block Node: content. Contents: [<TextNode: '\n<!-- Main content -->\n  '>, <Variable Node: 职位计数>, <TextNode: '</h3>\n              <p>职位'>, <django.template.defaulttags.URLNode object at 0x7f8a1e4fbd60>, <TextNode: '" class="small-box-footer'>, <Variable Node: 候选人计数>, <TextNode: '</h3>          \n         '>, <django.template.defaulttags.URLNode object at 0x7f8a1e4f9060>, <TextNode: '" class="small-box-footer'>, <Variable Node: 投票计数>, <TextNode: '</h3>             \n      '>, <django.template.defaulttags.URLNode object at 0x7f8a1f5c4310>, <TextNode: '" class="small-box-footer'>, <Variable Node: 已投票选民计数>, <TextNode: '</h3>\n              <p>已投'>, <django.template.defaulttags.URLNode object at 0x7f8a1e483bb0>, <TextNode: '" class="small-box-footer'>, <django.template.defaulttags.URLNode object at 0x7f8a1e483280>, <TextNode: '" class="btn btn-success '>, <ForNode: for position in positions, tail_len: 9>, <TextNode: '\n     '>, <IfNode>, <TextNode: '\n      </section>\n      \n'>]>}]
2024-06-09 03:57:10 django.template  /home/jn/.local/lib/python3.10/site-packages/django/template/base.py:869 base:_resolve_lookup DEBUG- Exception while resolving variable '职位计数' in template 'admin/home.html'.
Traceback (most recent call last):
  File "/home/jn/.local/lib/python3.10/site-packages/django/template/base.py", line 829, in _resolve_lookup
    current = current[bit]
  File "/home/jn/.local/lib/python3.10/site-packages/django/template/context.py", line 83, in __getitem__
    raise KeyError(key)
KeyError: '职位计数'

During handling of the above exception, another exception occurred:

Traceback (most recent call last):
  File "/home/jn/.local/lib/python3.10/site-packages/django/template/base.py", line 835, in _resolve_lookup
    if isinstance(current, BaseContext) and getattr(type(current), bit):
AttributeError: type object 'RequestContext' has no attribute '职位计数'

During handling of the above exception, another exception occurred:

Traceback (most recent call last):
  File "/home/jn/.local/lib/python3.10/site-packages/django/template/base.py", line 843, in _resolve_lookup
    current = current[int(bit)]
ValueError: invalid literal for int() with base 10: '职位计数'

During handling of the above exception, another exception occurred:

Traceback (most recent call last):
  File "/home/jn/.local/lib/python3.10/site-packages/django/template/base.py", line 848, in _resolve_lookup
    raise VariableDoesNotExist("Failed lookup for key "
django.template.base.VariableDoesNotExist: Failed lookup for key [职位计数] in [{'True': True, 'False': False, 'None': None}, {'csrf_token': <SimpleLazyObject: 'waLFiyH8D0cFFf9TuDRvUITQ6nLYQqtk82qIvzORuMXuri5HkLL8uGXhojzR8cO2'>, 'request': <WSGIRequest: GET '/administrator/'>, 'user': <SimpleLazyObject: <CustomUser: System Administrator>>, 'perms': <django.contrib.auth.context_processors.PermWrapper object at 0x7f8a1e20b970>, 'messages': <django.contrib.messages.storage.fallback.FallbackStorage object at 0x7f8a1e21d630>, 'DEFAULT_MESSAGE_LEVELS': {'DEBUG': 10, 'INFO': 20, 'SUCCESS': 25, 'WARNING': 30, 'ERROR': 40}, 'TITLE': '班级选举'}, {}, {'position_count': 1, 'candidate_count': 2, 'voters_count': 2, 'voted_voters_count': 2, 'positions': <QuerySet [<Position: q>]>, 'chart_data': {<Position: q>: {'candidates': ['a', 'b'], 'votes': [2, 0], 'pos_id': 1}}, 'page_title': '主页'}, {'block': <Block Node: content. Contents: [<TextNode: '\n<!-- Main content -->\n  '>, <Variable Node: 职位计数>, <TextNode: '</h3>\n              <p>职位'>, <django.template.defaulttags.URLNode object at 0x7f8a1e20b040>, <TextNode: '" class="small-box-footer'>, <Variable Node: 候选人计数>, <TextNode: '</h3>          \n         '>, <django.template.defaulttags.URLNode object at 0x7f8a1e20b790>, <TextNode: '" class="small-box-footer'>, <Variable Node: 投票计数>, <TextNode: '</h3>             \n      '>, <django.template.defaulttags.URLNode object at 0x7f8a1e20b520>, <TextNode: '" class="small-box-footer'>, <Variable Node: 已投票选民计数>, <TextNode: '</h3>\n              <p>已投'>, <django.template.defaulttags.URLNode object at 0x7f8a1e209ab0>, <TextNode: '" class="small-box-footer'>, <django.template.defaulttags.URLNode object at 0x7f8a1e20a770>, <TextNode: '" class="btn btn-success '>, <ForNode: for position in positions, tail_len: 9>, <TextNode: '\n     '>, <IfNode>, <TextNode: '\n      </section>\n      \n'>]>}]
2024-06-09 03:57:10 django.template  /home/jn/.local/lib/python3.10/site-packages/django/template/base.py:869 base:_resolve_lookup DEBUG- Exception while resolving variable '候选人计数' in template 'admin/home.html'.
Traceback (most recent call last):
  File "/home/jn/.local/lib/python3.10/site-packages/django/template/base.py", line 829, in _resolve_lookup
    current = current[bit]
  File "/home/jn/.local/lib/python3.10/site-packages/django/template/context.py", line 83, in __getitem__
    raise KeyError(key)
KeyError: '候选人计数'

During handling of the above exception, another exception occurred:

Traceback (most recent call last):
  File "/home/jn/.local/lib/python3.10/site-packages/django/template/base.py", line 835, in _resolve_lookup
    if isinstance(current, BaseContext) and getattr(type(current), bit):
AttributeError: type object 'RequestContext' has no attribute '候选人计数'

During handling of the above exception, another exception occurred:

Traceback (most recent call last):
  File "/home/jn/.local/lib/python3.10/site-packages/django/template/base.py", line 843, in _resolve_lookup
    current = current[int(bit)]
ValueError: invalid literal for int() with base 10: '候选人计数'

During handling of the above exception, another exception occurred:

Traceback (most recent call last):
  File "/home/jn/.local/lib/python3.10/site-packages/django/template/base.py", line 848, in _resolve_lookup
    raise VariableDoesNotExist("Failed lookup for key "
django.template.base.VariableDoesNotExist: Failed lookup for key [候选人计数] in [{'True': True, 'False': False, 'None': None}, {'csrf_token': <SimpleLazyObject: 'waLFiyH8D0cFFf9TuDRvUITQ6nLYQqtk82qIvzORuMXuri5HkLL8uGXhojzR8cO2'>, 'request': <WSGIRequest: GET '/administrator/'>, 'user': <SimpleLazyObject: <CustomUser: System Administrator>>, 'perms': <django.contrib.auth.context_processors.PermWrapper object at 0x7f8a1e20b970>, 'messages': <django.contrib.messages.storage.fallback.FallbackStorage object at 0x7f8a1e21d630>, 'DEFAULT_MESSAGE_LEVELS': {'DEBUG': 10, 'INFO': 20, 'SUCCESS': 25, 'WARNING': 30, 'ERROR': 40}, 'TITLE': '班级选举'}, {}, {'position_count': 1, 'candidate_count': 2, 'voters_count': 2, 'voted_voters_count': 2, 'positions': <QuerySet [<Position: q>]>, 'chart_data': {<Position: q>: {'candidates': ['a', 'b'], 'votes': [2, 0], 'pos_id': 1}}, 'page_title': '主页'}, {'block': <Block Node: content. Contents: [<TextNode: '\n<!-- Main content -->\n  '>, <Variable Node: 职位计数>, <TextNode: '</h3>\n              <p>职位'>, <django.template.defaulttags.URLNode object at 0x7f8a1e20b040>, <TextNode: '" class="small-box-footer'>, <Variable Node: 候选人计数>, <TextNode: '</h3>          \n         '>, <django.template.defaulttags.URLNode object at 0x7f8a1e20b790>, <TextNode: '" class="small-box-footer'>, <Variable Node: 投票计数>, <TextNode: '</h3>             \n      '>, <django.template.defaulttags.URLNode object at 0x7f8a1e20b520>, <TextNode: '" class="small-box-footer'>, <Variable Node: 已投票选民计数>, <TextNode: '</h3>\n              <p>已投'>, <django.template.defaulttags.URLNode object at 0x7f8a1e209ab0>, <TextNode: '" class="small-box-footer'>, <django.template.defaulttags.URLNode object at 0x7f8a1e20a770>, <TextNode: '" class="btn btn-success '>, <ForNode: for position in positions, tail_len: 9>, <TextNode: '\n     '>, <IfNode>, <TextNode: '\n      </section>\n      \n'>]>}]
2024-06-09 03:57:10 django.template  /home/jn/.local/lib/python3.10/site-packages/django/template/base.py:869 base:_resolve_lookup DEBUG- Exception while resolving variable '投票计数' in template 'admin/home.html'.
Traceback (most recent call last):
  File "/home/jn/.local/lib/python3.10/site-packages/django/template/base.py", line 829, in _resolve_lookup
    current = current[bit]
  File "/home/jn/.local/lib/python3.10/site-packages/django/template/context.py", line 83, in __getitem__
    raise KeyError(key)
KeyError: '投票计数'

During handling of the above exception, another exception occurred:

Traceback (most recent call last):
  File "/home/jn/.local/lib/python3.10/site-packages/django/template/base.py", line 835, in _resolve_lookup
    if isinstance(current, BaseContext) and getattr(type(current), bit):
AttributeError: type object 'RequestContext' has no attribute '投票计数'

During handling of the above exception, another exception occurred:

Traceback (most recent call last):
  File "/home/jn/.local/lib/python3.10/site-packages/django/template/base.py", line 843, in _resolve_lookup
    current = current[int(bit)]
ValueError: invalid literal for int() with base 10: '投票计数'

During handling of the above exception, another exception occurred:

Traceback (most recent call last):
  File "/home/jn/.local/lib/python3.10/site-packages/django/template/base.py", line 848, in _resolve_lookup
    raise VariableDoesNotExist("Failed lookup for key "
django.template.base.VariableDoesNotExist: Failed lookup for key [投票计数] in [{'True': True, 'False': False, 'None': None}, {'csrf_token': <SimpleLazyObject: 'waLFiyH8D0cFFf9TuDRvUITQ6nLYQqtk82qIvzORuMXuri5HkLL8uGXhojzR8cO2'>, 'request': <WSGIRequest: GET '/administrator/'>, 'user': <SimpleLazyObject: <CustomUser: System Administrator>>, 'perms': <django.contrib.auth.context_processors.PermWrapper object at 0x7f8a1e20b970>, 'messages': <django.contrib.messages.storage.fallback.FallbackStorage object at 0x7f8a1e21d630>, 'DEFAULT_MESSAGE_LEVELS': {'DEBUG': 10, 'INFO': 20, 'SUCCESS': 25, 'WARNING': 30, 'ERROR': 40}, 'TITLE': '班级选举'}, {}, {'position_count': 1, 'candidate_count': 2, 'voters_count': 2, 'voted_voters_count': 2, 'positions': <QuerySet [<Position: q>]>, 'chart_data': {<Position: q>: {'candidates': ['a', 'b'], 'votes': [2, 0], 'pos_id': 1}}, 'page_title': '主页'}, {'block': <Block Node: content. Contents: [<TextNode: '\n<!-- Main content -->\n  '>, <Variable Node: 职位计数>, <TextNode: '</h3>\n              <p>职位'>, <django.template.defaulttags.URLNode object at 0x7f8a1e20b040>, <TextNode: '" class="small-box-footer'>, <Variable Node: 候选人计数>, <TextNode: '</h3>          \n         '>, <django.template.defaulttags.URLNode object at 0x7f8a1e20b790>, <TextNode: '" class="small-box-footer'>, <Variable Node: 投票计数>, <TextNode: '</h3>             \n      '>, <django.template.defaulttags.URLNode object at 0x7f8a1e20b520>, <TextNode: '" class="small-box-footer'>, <Variable Node: 已投票选民计数>, <TextNode: '</h3>\n              <p>已投'>, <django.template.defaulttags.URLNode object at 0x7f8a1e209ab0>, <TextNode: '" class="small-box-footer'>, <django.template.defaulttags.URLNode object at 0x7f8a1e20a770>, <TextNode: '" class="btn btn-success '>, <ForNode: for position in positions, tail_len: 9>, <TextNode: '\n     '>, <IfNode>, <TextNode: '\n      </section>\n      \n'>]>}]
2024-06-09 03:57:10 django.template  /home/jn/.local/lib/python3.10/site-packages/django/template/base.py:869 base:_resolve_lookup DEBUG- Exception while resolving variable '已投票选民计数' in template 'admin/home.html'.
Traceback (most recent call last):
  File "/home/jn/.local/lib/python3.10/site-packages/django/template/base.py", line 829, in _resolve_lookup
    current = current[bit]
  File "/home/jn/.local/lib/python3.10/site-packages/django/template/context.py", line 83, in __getitem__
    raise KeyError(key)
KeyError: '已投票选民计数'

During handling of the above exception, another exception occurred:

Traceback (most recent call last):
  File "/home/jn/.local/lib/python3.10/site-packages/django/template/base.py", line 835, in _resolve_lookup
    if isinstance(current, BaseContext) and getattr(type(current), bit):
AttributeError: type object 'RequestContext' has no attribute '已投票选民计数'

During handling of the above exception, another exception occurred:

Traceback (most recent call last):
  File "/home/jn/.local/lib/python3.10/site-packages/django/template/base.py", line 843, in _resolve_lookup
    current = current[int(bit)]
ValueError: invalid literal for int() with base 10: '已投票选民计数'

During handling of the above exception, another exception occurred:

Traceback (most recent call last):
  File "/home/jn/.local/lib/python3.10/site-packages/django/template/base.py", line 848, in _resolve_lookup
    raise VariableDoesNotExist("Failed lookup for key "
django.template.base.VariableDoesNotExist: Failed lookup for key [已投票选民计数] in [{'True': True, 'False': False, 'None': None}, {'csrf_token': <SimpleLazyObject: 'waLFiyH8D0cFFf9TuDRvUITQ6nLYQqtk82qIvzORuMXuri5HkLL8uGXhojzR8cO2'>, 'request': <WSGIRequest: GET '/administrator/'>, 'user': <SimpleLazyObject: <CustomUser: System Administrator>>, 'perms': <django.contrib.auth.context_processors.PermWrapper object at 0x7f8a1e20b970>, 'messages': <django.contrib.messages.storage.fallback.FallbackStorage object at 0x7f8a1e21d630>, 'DEFAULT_MESSAGE_LEVELS': {'DEBUG': 10, 'INFO': 20, 'SUCCESS': 25, 'WARNING': 30, 'ERROR': 40}, 'TITLE': '班级选举'}, {}, {'position_count': 1, 'candidate_count': 2, 'voters_count': 2, 'voted_voters_count': 2, 'positions': <QuerySet [<Position: q>]>, 'chart_data': {<Position: q>: {'candidates': ['a', 'b'], 'votes': [2, 0], 'pos_id': 1}}, 'page_title': '主页'}, {'block': <Block Node: content. Contents: [<TextNode: '\n<!-- Main content -->\n  '>, <Variable Node: 职位计数>, <TextNode: '</h3>\n              <p>职位'>, <django.template.defaulttags.URLNode object at 0x7f8a1e20b040>, <TextNode: '" class="small-box-footer'>, <Variable Node: 候选人计数>, <TextNode: '</h3>          \n         '>, <django.template.defaulttags.URLNode object at 0x7f8a1e20b790>, <TextNode: '" class="small-box-footer'>, <Variable Node: 投票计数>, <TextNode: '</h3>             \n      '>, <django.template.defaulttags.URLNode object at 0x7f8a1e20b520>, <TextNode: '" class="small-box-footer'>, <Variable Node: 已投票选民计数>, <TextNode: '</h3>\n              <p>已投'>, <django.template.defaulttags.URLNode object at 0x7f8a1e209ab0>, <TextNode: '" class="small-box-footer'>, <django.template.defaulttags.URLNode object at 0x7f8a1e20a770>, <TextNode: '" class="btn btn-success '>, <ForNode: for position in positions, tail_len: 9>, <TextNode: '\n     '>, <IfNode>, <TextNode: '\n      </section>\n      \n'>]>}]
2024-06-09 03:57:10 django.template  /home/jn/.local/lib/python3.10/site-packages/django/template/base.py:869 base:_resolve_lookup DEBUG- Exception while resolving variable 'forloop' in template 'admin/home.html'.
Traceback (most recent call last):
  File "/home/jn/.local/lib/python3.10/site-packages/django/template/base.py", line 829, in _resolve_lookup
    current = current[bit]
  File "/home/jn/.local/lib/python3.10/site-packages/django/template/context.py", line 83, in __getitem__
    raise KeyError(key)
KeyError: 'forloop'

During handling of the above exception, another exception occurred:

Traceback (most recent call last):
  File "/home/jn/.local/lib/python3.10/site-packages/django/template/base.py", line 835, in _resolve_lookup
    if isinstance(current, BaseContext) and getattr(type(current), bit):
AttributeError: type object 'RequestContext' has no attribute 'forloop'

During handling of the above exception, another exception occurred:

Traceback (most recent call last):
  File "/home/jn/.local/lib/python3.10/site-packages/django/template/base.py", line 843, in _resolve_lookup
    current = current[int(bit)]
ValueError: invalid literal for int() with base 10: 'forloop'

During handling of the above exception, another exception occurred:

Traceback (most recent call last):
  File "/home/jn/.local/lib/python3.10/site-packages/django/template/base.py", line 848, in _resolve_lookup
    raise VariableDoesNotExist("Failed lookup for key "
django.template.base.VariableDoesNotExist: Failed lookup for key [forloop] in [{'True': True, 'False': False, 'None': None}, {'csrf_token': <SimpleLazyObject: 'waLFiyH8D0cFFf9TuDRvUITQ6nLYQqtk82qIvzORuMXuri5HkLL8uGXhojzR8cO2'>, 'request': <WSGIRequest: GET '/administrator/'>, 'user': <SimpleLazyObject: <CustomUser: System Administrator>>, 'perms': <django.contrib.auth.context_processors.PermWrapper object at 0x7f8a1e20b970>, 'messages': <django.contrib.messages.storage.fallback.FallbackStorage object at 0x7f8a1e21d630>, 'DEFAULT_MESSAGE_LEVELS': {'DEBUG': 10, 'INFO': 20, 'SUCCESS': 25, 'WARNING': 30, 'ERROR': 40}, 'TITLE': '班级选举'}, {}, {'position_count': 1, 'candidate_count': 2, 'voters_count': 2, 'voted_voters_count': 2, 'positions': <QuerySet [<Position: q>]>, 'chart_data': {<Position: q>: {'candidates': ['a', 'b'], 'votes': [2, 0], 'pos_id': 1}}, 'page_title': '主页'}, {'block': <Block Node: content. Contents: [<TextNode: '\n<!-- Main content -->\n  '>, <Variable Node: 职位计数>, <TextNode: '</h3>\n              <p>职位'>, <django.template.defaulttags.URLNode object at 0x7f8a1e20b040>, <TextNode: '" class="small-box-footer'>, <Variable Node: 候选人计数>, <TextNode: '</h3>          \n         '>, <django.template.defaulttags.URLNode object at 0x7f8a1e20b790>, <TextNode: '" class="small-box-footer'>, <Variable Node: 投票计数>, <TextNode: '</h3>             \n      '>, <django.template.defaulttags.URLNode object at 0x7f8a1e20b520>, <TextNode: '" class="small-box-footer'>, <Variable Node: 已投票选民计数>, <TextNode: '</h3>\n              <p>已投'>, <django.template.defaulttags.URLNode object at 0x7f8a1e209ab0>, <TextNode: '" class="small-box-footer'>, <django.template.defaulttags.URLNode object at 0x7f8a1e20a770>, <TextNode: '" class="btn btn-success '>, <ForNode: for position in positions, tail_len: 9>, <TextNode: '\n     '>, <IfNode>, <TextNode: '\n      </section>\n      \n'>]>}]
2024-06-09 04:00:02 django.template  /home/jn/.local/lib/python3.10/site-packages/django/template/base.py:869 base:_resolve_lookup DEBUG- Exception while resolving variable '职位计数' in template 'admin/home.html'.
Traceback (most recent call last):
  File "/home/jn/.local/lib/python3.10/site-packages/django/template/base.py", line 829, in _resolve_lookup
    current = current[bit]
  File "/home/jn/.local/lib/python3.10/site-packages/django/template/context.py", line 83, in __getitem__
    raise KeyError(key)
KeyError: '职位计数'

During handling of the above exception, another exception occurred:

Traceback (most recent call last):
  File "/home/jn/.local/lib/python3.10/site-packages/django/template/base.py", line 835, in _resolve_lookup
    if isinstance(current, BaseContext) and getattr(type(current), bit):
AttributeError: type object 'RequestContext' has no attribute '职位计数'

During handling of the above exception, another exception occurred:

Traceback (most recent call last):
  File "/home/jn/.local/lib/python3.10/site-packages/django/template/base.py", line 843, in _resolve_lookup
    current = current[int(bit)]
ValueError: invalid literal for int() with base 10: '职位计数'

During handling of the above exception, another exception occurred:

Traceback (most recent call last):
  File "/home/jn/.local/lib/python3.10/site-packages/django/template/base.py", line 848, in _resolve_lookup
    raise VariableDoesNotExist("Failed lookup for key "
django.template.base.VariableDoesNotExist: Failed lookup for key [职位计数] in [{'True': True, 'False': False, 'None': None}, {'csrf_token': <SimpleLazyObject: 'I706BMyGSt7B2oxEesLalaGXhIjBxEOykZF9ONFpJfSqOrts4AFNV8KozE7uPq9g'>, 'request': <WSGIRequest: GET '/administrator/'>, 'user': <SimpleLazyObject: <CustomUser: System Administrator>>, 'perms': <django.contrib.auth.context_processors.PermWrapper object at 0x7f8a1e42bbb0>, 'messages': <django.contrib.messages.storage.fallback.FallbackStorage object at 0x7f8a1e4fb5b0>, 'DEFAULT_MESSAGE_LEVELS': {'DEBUG': 10, 'INFO': 20, 'SUCCESS': 25, 'WARNING': 30, 'ERROR': 40}, 'TITLE': '学校选举'}, {}, {'position_count': 1, 'candidate_count': 2, 'voters_count': 2, 'voted_voters_count': 2, 'positions': <QuerySet [<Position: 校长>]>, 'chart_data': {<Position: 校长>: {'candidates': ['a', 'b'], 'votes': [0, 0], 'pos_id': 2}}, 'page_title': '主页'}, {'block': <Block Node: content. Contents: [<TextNode: '\n<!-- Main content -->\n  '>, <Variable Node: 职位计数>, <TextNode: '</h3>\n              <p>职位'>, <django.template.defaulttags.URLNode object at 0x7f8a261b2c80>, <TextNode: '" class="small-box-footer'>, <Variable Node: 候选人计数>, <TextNode: '</h3>          \n         '>, <django.template.defaulttags.URLNode object at 0x7f8a261b1630>, <TextNode: '" class="small-box-footer'>, <Variable Node: 投票计数>, <TextNode: '</h3>             \n      '>, <django.template.defaulttags.URLNode object at 0x7f8a261b1960>, <TextNode: '" class="small-box-footer'>, <Variable Node: 已投票选民计数>, <TextNode: '</h3>\n              <p>已投'>, <django.template.defaulttags.URLNode object at 0x7f8a26214460>, <TextNode: '" class="small-box-footer'>, <django.template.defaulttags.URLNode object at 0x7f8a262144f0>, <TextNode: '" class="btn btn-success '>, <ForNode: for position in positions, tail_len: 9>, <TextNode: '\n     '>, <IfNode>, <TextNode: '\n      </section>\n      \n'>]>}]
2024-06-09 04:00:02 django.template  /home/jn/.local/lib/python3.10/site-packages/django/template/base.py:869 base:_resolve_lookup DEBUG- Exception while resolving variable '候选人计数' in template 'admin/home.html'.
Traceback (most recent call last):
  File "/home/jn/.local/lib/python3.10/site-packages/django/template/base.py", line 829, in _resolve_lookup
    current = current[bit]
  File "/home/jn/.local/lib/python3.10/site-packages/django/template/context.py", line 83, in __getitem__
    raise KeyError(key)
KeyError: '候选人计数'

During handling of the above exception, another exception occurred:

Traceback (most recent call last):
  File "/home/jn/.local/lib/python3.10/site-packages/django/template/base.py", line 835, in _resolve_lookup
    if isinstance(current, BaseContext) and getattr(type(current), bit):
AttributeError: type object 'RequestContext' has no attribute '候选人计数'

During handling of the above exception, another exception occurred:

Traceback (most recent call last):
  File "/home/jn/.local/lib/python3.10/site-packages/django/template/base.py", line 843, in _resolve_lookup
    current = current[int(bit)]
ValueError: invalid literal for int() with base 10: '候选人计数'

During handling of the above exception, another exception occurred:

Traceback (most recent call last):
  File "/home/jn/.local/lib/python3.10/site-packages/django/template/base.py", line 848, in _resolve_lookup
    raise VariableDoesNotExist("Failed lookup for key "
django.template.base.VariableDoesNotExist: Failed lookup for key [候选人计数] in [{'True': True, 'False': False, 'None': None}, {'csrf_token': <SimpleLazyObject: 'I706BMyGSt7B2oxEesLalaGXhIjBxEOykZF9ONFpJfSqOrts4AFNV8KozE7uPq9g'>, 'request': <WSGIRequest: GET '/administrator/'>, 'user': <SimpleLazyObject: <CustomUser: System Administrator>>, 'perms': <django.contrib.auth.context_processors.PermWrapper object at 0x7f8a1e42bbb0>, 'messages': <django.contrib.messages.storage.fallback.FallbackStorage object at 0x7f8a1e4fb5b0>, 'DEFAULT_MESSAGE_LEVELS': {'DEBUG': 10, 'INFO': 20, 'SUCCESS': 25, 'WARNING': 30, 'ERROR': 40}, 'TITLE': '学校选举'}, {}, {'position_count': 1, 'candidate_count': 2, 'voters_count': 2, 'voted_voters_count': 2, 'positions': <QuerySet [<Position: 校长>]>, 'chart_data': {<Position: 校长>: {'candidates': ['a', 'b'], 'votes': [0, 0], 'pos_id': 2}}, 'page_title': '主页'}, {'block': <Block Node: content. Contents: [<TextNode: '\n<!-- Main content -->\n  '>, <Variable Node: 职位计数>, <TextNode: '</h3>\n              <p>职位'>, <django.template.defaulttags.URLNode object at 0x7f8a261b2c80>, <TextNode: '" class="small-box-footer'>, <Variable Node: 候选人计数>, <TextNode: '</h3>          \n         '>, <django.template.defaulttags.URLNode object at 0x7f8a261b1630>, <TextNode: '" class="small-box-footer'>, <Variable Node: 投票计数>, <TextNode: '</h3>             \n      '>, <django.template.defaulttags.URLNode object at 0x7f8a261b1960>, <TextNode: '" class="small-box-footer'>, <Variable Node: 已投票选民计数>, <TextNode: '</h3>\n              <p>已投'>, <django.template.defaulttags.URLNode object at 0x7f8a26214460>, <TextNode: '" class="small-box-footer'>, <django.template.defaulttags.URLNode object at 0x7f8a262144f0>, <TextNode: '" class="btn btn-success '>, <ForNode: for position in positions, tail_len: 9>, <TextNode: '\n     '>, <IfNode>, <TextNode: '\n      </section>\n      \n'>]>}]
2024-06-09 04:00:02 django.template  /home/jn/.local/lib/python3.10/site-packages/django/template/base.py:869 base:_resolve_lookup DEBUG- Exception while resolving variable '投票计数' in template 'admin/home.html'.
Traceback (most recent call last):
  File "/home/jn/.local/lib/python3.10/site-packages/django/template/base.py", line 829, in _resolve_lookup
    current = current[bit]
  File "/home/jn/.local/lib/python3.10/site-packages/django/template/context.py", line 83, in __getitem__
    raise KeyError(key)
KeyError: '投票计数'

During handling of the above exception, another exception occurred:

Traceback (most recent call last):
  File "/home/jn/.local/lib/python3.10/site-packages/django/template/base.py", line 835, in _resolve_lookup
    if isinstance(current, BaseContext) and getattr(type(current), bit):
AttributeError: type object 'RequestContext' has no attribute '投票计数'

During handling of the above exception, another exception occurred:

Traceback (most recent call last):
  File "/home/jn/.local/lib/python3.10/site-packages/django/template/base.py", line 843, in _resolve_lookup
    current = current[int(bit)]
ValueError: invalid literal for int() with base 10: '投票计数'

During handling of the above exception, another exception occurred:

Traceback (most recent call last):
  File "/home/jn/.local/lib/python3.10/site-packages/django/template/base.py", line 848, in _resolve_lookup
    raise VariableDoesNotExist("Failed lookup for key "
django.template.base.VariableDoesNotExist: Failed lookup for key [投票计数] in [{'True': True, 'False': False, 'None': None}, {'csrf_token': <SimpleLazyObject: 'I706BMyGSt7B2oxEesLalaGXhIjBxEOykZF9ONFpJfSqOrts4AFNV8KozE7uPq9g'>, 'request': <WSGIRequest: GET '/administrator/'>, 'user': <SimpleLazyObject: <CustomUser: System Administrator>>, 'perms': <django.contrib.auth.context_processors.PermWrapper object at 0x7f8a1e42bbb0>, 'messages': <django.contrib.messages.storage.fallback.FallbackStorage object at 0x7f8a1e4fb5b0>, 'DEFAULT_MESSAGE_LEVELS': {'DEBUG': 10, 'INFO': 20, 'SUCCESS': 25, 'WARNING': 30, 'ERROR': 40}, 'TITLE': '学校选举'}, {}, {'position_count': 1, 'candidate_count': 2, 'voters_count': 2, 'voted_voters_count': 2, 'positions': <QuerySet [<Position: 校长>]>, 'chart_data': {<Position: 校长>: {'candidates': ['a', 'b'], 'votes': [0, 0], 'pos_id': 2}}, 'page_title': '主页'}, {'block': <Block Node: content. Contents: [<TextNode: '\n<!-- Main content -->\n  '>, <Variable Node: 职位计数>, <TextNode: '</h3>\n              <p>职位'>, <django.template.defaulttags.URLNode object at 0x7f8a261b2c80>, <TextNode: '" class="small-box-footer'>, <Variable Node: 候选人计数>, <TextNode: '</h3>          \n         '>, <django.template.defaulttags.URLNode object at 0x7f8a261b1630>, <TextNode: '" class="small-box-footer'>, <Variable Node: 投票计数>, <TextNode: '</h3>             \n      '>, <django.template.defaulttags.URLNode object at 0x7f8a261b1960>, <TextNode: '" class="small-box-footer'>, <Variable Node: 已投票选民计数>, <TextNode: '</h3>\n              <p>已投'>, <django.template.defaulttags.URLNode object at 0x7f8a26214460>, <TextNode: '" class="small-box-footer'>, <django.template.defaulttags.URLNode object at 0x7f8a262144f0>, <TextNode: '" class="btn btn-success '>, <ForNode: for position in positions, tail_len: 9>, <TextNode: '\n     '>, <IfNode>, <TextNode: '\n      </section>\n      \n'>]>}]
2024-06-09 04:00:02 django.template  /home/jn/.local/lib/python3.10/site-packages/django/template/base.py:869 base:_resolve_lookup DEBUG- Exception while resolving variable '已投票选民计数' in template 'admin/home.html'.
Traceback (most recent call last):
  File "/home/jn/.local/lib/python3.10/site-packages/django/template/base.py", line 829, in _resolve_lookup
    current = current[bit]
  File "/home/jn/.local/lib/python3.10/site-packages/django/template/context.py", line 83, in __getitem__
    raise KeyError(key)
KeyError: '已投票选民计数'

During handling of the above exception, another exception occurred:

Traceback (most recent call last):
  File "/home/jn/.local/lib/python3.10/site-packages/django/template/base.py", line 835, in _resolve_lookup
    if isinstance(current, BaseContext) and getattr(type(current), bit):
AttributeError: type object 'RequestContext' has no attribute '已投票选民计数'

During handling of the above exception, another exception occurred:

Traceback (most recent call last):
  File "/home/jn/.local/lib/python3.10/site-packages/django/template/base.py", line 843, in _resolve_lookup
    current = current[int(bit)]
ValueError: invalid literal for int() with base 10: '已投票选民计数'

During handling of the above exception, another exception occurred:

Traceback (most recent call last):
  File "/home/jn/.local/lib/python3.10/site-packages/django/template/base.py", line 848, in _resolve_lookup
    raise VariableDoesNotExist("Failed lookup for key "
django.template.base.VariableDoesNotExist: Failed lookup for key [已投票选民计数] in [{'True': True, 'False': False, 'None': None}, {'csrf_token': <SimpleLazyObject: 'I706BMyGSt7B2oxEesLalaGXhIjBxEOykZF9ONFpJfSqOrts4AFNV8KozE7uPq9g'>, 'request': <WSGIRequest: GET '/administrator/'>, 'user': <SimpleLazyObject: <CustomUser: System Administrator>>, 'perms': <django.contrib.auth.context_processors.PermWrapper object at 0x7f8a1e42bbb0>, 'messages': <django.contrib.messages.storage.fallback.FallbackStorage object at 0x7f8a1e4fb5b0>, 'DEFAULT_MESSAGE_LEVELS': {'DEBUG': 10, 'INFO': 20, 'SUCCESS': 25, 'WARNING': 30, 'ERROR': 40}, 'TITLE': '学校选举'}, {}, {'position_count': 1, 'candidate_count': 2, 'voters_count': 2, 'voted_voters_count': 2, 'positions': <QuerySet [<Position: 校长>]>, 'chart_data': {<Position: 校长>: {'candidates': ['a', 'b'], 'votes': [0, 0], 'pos_id': 2}}, 'page_title': '主页'}, {'block': <Block Node: content. Contents: [<TextNode: '\n<!-- Main content -->\n  '>, <Variable Node: 职位计数>, <TextNode: '</h3>\n              <p>职位'>, <django.template.defaulttags.URLNode object at 0x7f8a261b2c80>, <TextNode: '" class="small-box-footer'>, <Variable Node: 候选人计数>, <TextNode: '</h3>          \n         '>, <django.template.defaulttags.URLNode object at 0x7f8a261b1630>, <TextNode: '" class="small-box-footer'>, <Variable Node: 投票计数>, <TextNode: '</h3>             \n      '>, <django.template.defaulttags.URLNode object at 0x7f8a261b1960>, <TextNode: '" class="small-box-footer'>, <Variable Node: 已投票选民计数>, <TextNode: '</h3>\n              <p>已投'>, <django.template.defaulttags.URLNode object at 0x7f8a26214460>, <TextNode: '" class="small-box-footer'>, <django.template.defaulttags.URLNode object at 0x7f8a262144f0>, <TextNode: '" class="btn btn-success '>, <ForNode: for position in positions, tail_len: 9>, <TextNode: '\n     '>, <IfNode>, <TextNode: '\n      </section>\n      \n'>]>}]
2024-06-09 04:00:02 django.template  /home/jn/.local/lib/python3.10/site-packages/django/template/base.py:869 base:_resolve_lookup DEBUG- Exception while resolving variable 'forloop' in template 'admin/home.html'.
Traceback (most recent call last):
  File "/home/jn/.local/lib/python3.10/site-packages/django/template/base.py", line 829, in _resolve_lookup
    current = current[bit]
  File "/home/jn/.local/lib/python3.10/site-packages/django/template/context.py", line 83, in __getitem__
    raise KeyError(key)
KeyError: 'forloop'

During handling of the above exception, another exception occurred:

Traceback (most recent call last):
  File "/home/jn/.local/lib/python3.10/site-packages/django/template/base.py", line 835, in _resolve_lookup
    if isinstance(current, BaseContext) and getattr(type(current), bit):
AttributeError: type object 'RequestContext' has no attribute 'forloop'

During handling of the above exception, another exception occurred:

Traceback (most recent call last):
  File "/home/jn/.local/lib/python3.10/site-packages/django/template/base.py", line 843, in _resolve_lookup
    current = current[int(bit)]
ValueError: invalid literal for int() with base 10: 'forloop'

During handling of the above exception, another exception occurred:

Traceback (most recent call last):
  File "/home/jn/.local/lib/python3.10/site-packages/django/template/base.py", line 848, in _resolve_lookup
    raise VariableDoesNotExist("Failed lookup for key "
django.template.base.VariableDoesNotExist: Failed lookup for key [forloop] in [{'True': True, 'False': False, 'None': None}, {'csrf_token': <SimpleLazyObject: 'I706BMyGSt7B2oxEesLalaGXhIjBxEOykZF9ONFpJfSqOrts4AFNV8KozE7uPq9g'>, 'request': <WSGIRequest: GET '/administrator/'>, 'user': <SimpleLazyObject: <CustomUser: System Administrator>>, 'perms': <django.contrib.auth.context_processors.PermWrapper object at 0x7f8a1e42bbb0>, 'messages': <django.contrib.messages.storage.fallback.FallbackStorage object at 0x7f8a1e4fb5b0>, 'DEFAULT_MESSAGE_LEVELS': {'DEBUG': 10, 'INFO': 20, 'SUCCESS': 25, 'WARNING': 30, 'ERROR': 40}, 'TITLE': '学校选举'}, {}, {'position_count': 1, 'candidate_count': 2, 'voters_count': 2, 'voted_voters_count': 2, 'positions': <QuerySet [<Position: 校长>]>, 'chart_data': {<Position: 校长>: {'candidates': ['a', 'b'], 'votes': [0, 0], 'pos_id': 2}}, 'page_title': '主页'}, {'block': <Block Node: content. Contents: [<TextNode: '\n<!-- Main content -->\n  '>, <Variable Node: 职位计数>, <TextNode: '</h3>\n              <p>职位'>, <django.template.defaulttags.URLNode object at 0x7f8a261b2c80>, <TextNode: '" class="small-box-footer'>, <Variable Node: 候选人计数>, <TextNode: '</h3>          \n         '>, <django.template.defaulttags.URLNode object at 0x7f8a261b1630>, <TextNode: '" class="small-box-footer'>, <Variable Node: 投票计数>, <TextNode: '</h3>             \n      '>, <django.template.defaulttags.URLNode object at 0x7f8a261b1960>, <TextNode: '" class="small-box-footer'>, <Variable Node: 已投票选民计数>, <TextNode: '</h3>\n              <p>已投'>, <django.template.defaulttags.URLNode object at 0x7f8a26214460>, <TextNode: '" class="small-box-footer'>, <django.template.defaulttags.URLNode object at 0x7f8a262144f0>, <TextNode: '" class="btn btn-success '>, <ForNode: for position in positions, tail_len: 9>, <TextNode: '\n     '>, <IfNode>, <TextNode: '\n      </section>\n      \n'>]>}]
2024-06-09 04:00:32 django.template  /home/jn/.local/lib/python3.10/site-packages/django/template/base.py:869 base:_resolve_lookup DEBUG- Exception while resolving variable 'page_title' in template 'voting/voter/result.html'.
Traceback (most recent call last):
  File "/home/jn/.local/lib/python3.10/site-packages/django/template/base.py", line 829, in _resolve_lookup
    current = current[bit]
  File "/home/jn/.local/lib/python3.10/site-packages/django/template/context.py", line 83, in __getitem__
    raise KeyError(key)
KeyError: 'page_title'

During handling of the above exception, another exception occurred:

Traceback (most recent call last):
  File "/home/jn/.local/lib/python3.10/site-packages/django/template/base.py", line 835, in _resolve_lookup
    if isinstance(current, BaseContext) and getattr(type(current), bit):
AttributeError: type object 'RequestContext' has no attribute 'page_title'

During handling of the above exception, another exception occurred:

Traceback (most recent call last):
  File "/home/jn/.local/lib/python3.10/site-packages/django/template/base.py", line 843, in _resolve_lookup
    current = current[int(bit)]
ValueError: invalid literal for int() with base 10: 'page_title'

During handling of the above exception, another exception occurred:

Traceback (most recent call last):
  File "/home/jn/.local/lib/python3.10/site-packages/django/template/base.py", line 848, in _resolve_lookup
    raise VariableDoesNotExist("Failed lookup for key "
django.template.base.VariableDoesNotExist: Failed lookup for key [page_title] in [{'True': True, 'False': False, 'None': None}, {'csrf_token': <SimpleLazyObject: 'UXtAjHHEZK218ZJLlrrblZm2VTBMSFe3uE7Wia73hunRVxc33oADOLKhyW9So0u2'>, 'request': <WSGIRequest: GET '/voting/dashboard/'>, 'user': <SimpleLazyObject: <CustomUser: 橙 子>>, 'perms': <django.contrib.auth.context_processors.PermWrapper object at 0x7f8a26215b70>, 'messages': <django.contrib.messages.storage.fallback.FallbackStorage object at 0x7f8a261f84f0>, 'DEFAULT_MESSAGE_LEVELS': {'DEBUG': 10, 'INFO': 20, 'SUCCESS': 25, 'WARNING': 30, 'ERROR': 40}, 'TITLE': '学校选举'}, {}, {'my_votes': <QuerySet []>}]
2024-06-09 04:00:32 django.template  /home/jn/.local/lib/python3.10/site-packages/django/template/base.py:869 base:_resolve_lookup DEBUG- Exception while resolving variable 'page_title' in template 'voting/voter/result.html'.
Traceback (most recent call last):
  File "/home/jn/.local/lib/python3.10/site-packages/django/template/base.py", line 829, in _resolve_lookup
    current = current[bit]
  File "/home/jn/.local/lib/python3.10/site-packages/django/template/context.py", line 83, in __getitem__
    raise KeyError(key)
KeyError: 'page_title'

During handling of the above exception, another exception occurred:

Traceback (most recent call last):
  File "/home/jn/.local/lib/python3.10/site-packages/django/template/base.py", line 835, in _resolve_lookup
    if isinstance(current, BaseContext) and getattr(type(current), bit):
AttributeError: type object 'RequestContext' has no attribute 'page_title'

During handling of the above exception, another exception occurred:

Traceback (most recent call last):
  File "/home/jn/.local/lib/python3.10/site-packages/django/template/base.py", line 843, in _resolve_lookup
    current = current[int(bit)]
ValueError: invalid literal for int() with base 10: 'page_title'

During handling of the above exception, another exception occurred:

Traceback (most recent call last):
  File "/home/jn/.local/lib/python3.10/site-packages/django/template/base.py", line 848, in _resolve_lookup
    raise VariableDoesNotExist("Failed lookup for key "
django.template.base.VariableDoesNotExist: Failed lookup for key [page_title] in [{'True': True, 'False': False, 'None': None}, {'csrf_token': <SimpleLazyObject: 'UXtAjHHEZK218ZJLlrrblZm2VTBMSFe3uE7Wia73hunRVxc33oADOLKhyW9So0u2'>, 'request': <WSGIRequest: GET '/voting/dashboard/'>, 'user': <SimpleLazyObject: <CustomUser: 橙 子>>, 'perms': <django.contrib.auth.context_processors.PermWrapper object at 0x7f8a26215b70>, 'messages': <django.contrib.messages.storage.fallback.FallbackStorage object at 0x7f8a261f84f0>, 'DEFAULT_MESSAGE_LEVELS': {'DEBUG': 10, 'INFO': 20, 'SUCCESS': 25, 'WARNING': 30, 'ERROR': 40}, 'TITLE': '学校选举'}, {}, {'my_votes': <QuerySet []>}]
